Workbook

Sheet Dataset
A1: Project_ID | B1: 프로젝트명 | C1: 투자유형 | D1: 세부유형 | E1: 자본구조1(SAP) | F1: 약정통화 | G1: 최초인출일 | H1: 만기일 | I1: 빈티지 | J1: 종목ID/트렌치ID(대표) | K1: Asset_Class_EN | L1: Asset_Name_EN | M1: Manager_EN | N1: Manager_EN_2 | O1: Region_EN | P1: Strategy | Q1: Sector | R1: 약정금액(원화)_합계 | S1: 실행(누적)_합계 | T1: 상환(누적)_합계 | U1: 장부가액(원화)_합계 | V1: 평가금액(원화)_합계 | W1: 수익률(원화,누적)_대표 | X1: 트렌치수 | Y1: 하위자산수
A2: BS00000004 | B2: =IF($A2="","",IFERROR(VLOOKUP($A2,AI_PF!$A:$D,4,FALSE),"")) -> 서울고속도로 리파이낸싱 | C2: =IF($A2="","",IFERROR(VLOOKUP($A2,AI_PF!$A:$G,7,FALSE),"")) -> BTO | D2: =IF($A2="","",IFERROR(VLOOKUP($A2,AI_PF!$A:$H,8,FALSE),"")) -> 도로 | E2: =IF($A2="","",IFERROR(VLOOKUP($A2,AI_PF!$A:$N,14,FALSE),"")) -> 대출 | F2: =IF($A2="","",IFERROR(VLOOKUP($A2,AI_PF!$A:$R,18,FALSE),"")) -> KRW | G2: =IF($A2="","",IFERROR(VLOOKUP($A2,AI_PF!$A:$T,20,FALSE),"")) -> 40723 | H2: =IF($A2="","",IFERROR(VLOOKUP($A2,AI_PF!$A:$V,22,FALSE),"")) -> 48394 | I2: =IF($A2="","",IFERROR(VLOOKUP($A2,AI_PF!$A:$EU,151,FALSE),"")) -> ~2016 | J2: =IF($A2="","",IFERROR(VLOOKUP($A2,AI_PF!$A:$C,3,FALSE),"")) -> 6000000000138 | K2: =IF($A2="","",IFERROR(VLOOKUP($A2,Data_Raw!$A:$G,2,FALSE),"")) -> Infrastructure | L2: =IF($A2="","",IFERROR(VLOOKUP($A2,Data_Raw!$A:$G,3,FALSE),"")) -> 서울고속도로 리파이낸싱 | M2: =IF($A2="","",IFERROR(VLOOKUP($A2,Data_Raw!$A:$G,4,FALSE),"")) -> 칸서스자산운용 | N2: =IF($A2="","",IFERROR(VLOOKUP($A2,AI_PF!$A:$EU,29,FALSE),"")) -> 해당없음 | O2: =IF($A2="","",IFERROR(VLOOKUP($A2,Data_Raw!$A:$G,5,FALSE),"")) -> KOR | P2: =IF($A2="","",IFERROR(VLOOKUP($A2,Data_Raw!$A:$G,6,FALSE),"")) -> BTO | Q2: =IF($A2="","",IFERROR(VLOOKUP($A2,Data_Raw!$A:$G,7,FALSE),"")) -> Transportation | R2: =IF($A2="","",SUMIFS(AI_PF!$AP:$AP,AI_PF!$A:$A,$A2)) -> 14000000000 | S2: =IF($A2="","",SUMIFS(AI_PF!$AW:$AW,AI_PF!$A:$A,$A2)) -> 14000000000 | T2: =IF($A2="","",SUMIFS(AI_PF!$AZ:$AZ,AI_PF!$A:$A,$A2)) -> 4737712417 | U2: =IF($A2="","",SUMIFS(AI_PF!$CA:$CA,AI_PF!$A:$A,$A2)) -> 9275000000 | V2: =IF($A2="","",SUMIFS(AI_PF!$CE:$CE,AI_PF!$A:$A,$A2)) -> 9262287583 | W2: =IF($A2="","",IFERROR(VLOOKUP($A2,AI_PF!$A:$CO,93,FALSE),"")) -> 7.4321597 | X2: =IF($A2="","",COUNTIF(AI_PF!$A:$A,$A2)) -> 1 | Y2: =IF($A2="","",COUNTIF(LookThrough!$A:$A,J2)) -> 0
A3: BS00000005 | B3: =IF($A3="","",IFERROR(VLOOKUP($A3,AI_PF!$A:$D,4,FALSE),"")) -> 신공항하이웨이 리파이낸싱 (지분) | C3: =IF($A3="","",IFERROR(VLOOKUP($A3,AI_PF!$A:$G,7,FALSE),"")) -> BTO | D3: =IF($A3="","",IFERROR(VLOOKUP($A3,AI_PF!$A:$H,8,FALSE),"")) -> 도로 | E3: =IF($A3="","",IFERROR(VLOOKUP($A3,AI_PF!$A:$N,14,FALSE),"")) -> 출자 | F3: =IF($A3="","",IFERROR(VLOOKUP($A3,AI_PF!$A:$R,18,FALSE),"")) -> KRW | G3: =IF($A3="","",IFERROR(VLOOKUP($A3,AI_PF!$A:$T,20,FALSE),"")) -> 37984 | H3: =IF($A3="","",IFERROR(VLOOKUP($A3,AI_PF!$A:$V,22,FALSE),"")) -> 2958465 | I3: =IF($A3="","",IFERROR(VLOOKUP($A3,AI_PF!$A:$EU,151,FALSE),"")) -> ~2016 | J3: =IF($A3="","",IFERROR(VLOOKUP($A3,AI_PF!$A:$C,3,FALSE),"")) -> 100001946 | K3: =IF($A3="","",IFERROR(VLOOKUP($A3,Data_Raw!$A:$G,2,FALSE),"")) -> Infrastructure | L3: =IF($A3="","",IFERROR(VLOOKUP($A3,Data_Raw!$A:$G,3,FALSE),"")) -> 신공항하이웨이 리파이낸싱 (지분) | M3: =IF($A3="","",IFERROR(VLOOKUP($A3,Data_Raw!$A:$G,4,FALSE),"")) -> 우리은행 | N3: =IF($A3="","",IFERROR(VLOOKUP($A3,AI_PF!$A:$EU,29,FALSE),"")) -> 해당없음 | O3: =IF($A3="","",IFERROR(VLOOKUP($A3,Data_Raw!$A:$G,5,FALSE),"")) -> KOR | P3: =IF($A3="","",IFERROR(VLOOKUP($A3,Data_Raw!$A:$G,6,FALSE),"")) -> BTO | Q3: =IF($A3="","",IFERROR(VLOOKUP($A3,Data_Raw!$A:$G,7,FALSE),"")) -> Transportation | R3: =IF($A3="","",SUMIFS(AI_PF!$AP:$AP,AI_PF!$A:$A,$A3)) -> 8453000000 | S3: =IF($A3="","",SUMIFS(AI_PF!$AW:$AW,AI_PF!$A:$A,$A3)) -> 0 | T3: =IF($A3="","",SUMIFS(AI_PF!$AZ:$AZ,AI_PF!$A:$A,$A3)) -> 5031495000 | U3: =IF($A3="","",SUMIFS(AI_PF!$CA:$CA,AI_PF!$A:$A,$A3)) -> 7992109627 | V3: =IF($A3="","",SUMIFS(AI_PF!$CE:$CE,AI_PF!$A:$A,$A3)) -> 7992109627 | W3: =IF($A3="","",IFERROR(VLOOKUP($A3,AI_PF!$A:$CO,93,FALSE),"")) -> 0 | X3: =IF($A3="","",COUNTIF(AI_PF!$A:$A,$A3)) -> 1 | Y3: =IF($A3="","",COUNTIF(LookThrough!$A:$A,J3)) -> 0
A4: BS00000009 | B4: =IF($A4="","",IFERROR(VLOOKUP($A4,AI_PF!$A:$D,4,FALSE),"")) -> 광주제2순환도로 리파이낸싱 | C4: =IF($A4="","",IFERROR(VLOOKUP($A4,AI_PF!$A:$G,7,FALSE),"")) -> BTO | D4: =IF($A4="","",IFERROR(VLOOKUP($A4,AI_PF!$A:$H,8,FALSE),"")) -> 도로 | E4: =IF($A4="","",IFERROR(VLOOKUP($A4,AI_PF!$A:$N,14,FALSE),"")) -> 대출 | F4: =IF($A4="","",IFERROR(VLOOKUP($A4,AI_PF!$A:$R,18,FALSE),"")) -> KRW | G4: =IF($A4="","",IFERROR(VLOOKUP($A4,AI_PF!$A:$T,20,FALSE),"")) -> 41074 | H4: =IF($A4="","",IFERROR(VLOOKUP($A4,AI_PF!$A:$V,22,FALSE),"")) -> 48196 | I4: =IF($A4="","",IFERROR(VLOOKUP($A4,AI_PF!$A:$EU,151,FALSE),"")) -> ~2016 | J4: =IF($A4="","",IFERROR(VLOOKUP($A4,AI_PF!$A:$C,3,FALSE),"")) -> 6000000000220 | K4: =IF($A4="","",IFERROR(VLOOKUP($A4,Data_Raw!$A:$G,2,FALSE),"")) -> Infrastructure | L4: =IF($A4="","",IFERROR(VLOOKUP($A4,Data_Raw!$A:$G,3,FALSE),"")) -> 광주제2순환도로 리파이낸싱 | M4: =IF($A4="","",IFERROR(VLOOKUP($A4,Data_Raw!$A:$G,4,FALSE),"")) -> 신한자산운용 | N4: =IF($A4="","",IFERROR(VLOOKUP($A4,AI_PF!$A:$EU,29,FALSE),"")) -> 해당없음 | O4: =IF($A4="","",IFERROR(VLOOKUP($A4,Data_Raw!$A:$G,5,FALSE),"")) -> KOR | P4: =IF($A4="","",IFERROR(VLOOKUP($A4,Data_Raw!$A:$G,6,FALSE),"")) -> BTO | Q4: =IF($A4="","",IFERROR(VLOOKUP($A4,Data_Raw!$A:$G,7,FALSE),"")) -> Transportation | R4: =IF($A4="","",SUMIFS(AI_PF!$AP:$AP,AI_PF!$A:$A,$A4)) -> 48820000000 | S4: =IF($A4="","",SUMIFS(AI_PF!$AW:$AW,AI_PF!$A:$A,$A4)) -> 38817500000 | T4: =IF($A4="","",SUMIFS(AI_PF!$AZ:$AZ,AI_PF!$A:$A,$A4)) -> 13037382925 | U4: =IF($A4="","",SUMIFS(AI_PF!$CA:$CA,AI_PF!$A:$A,$A4)) -> 30509431114 | V4: =IF($A4="","",SUMIFS(AI_PF!$CE:$CE,AI_PF!$A:$A,$A4)) -> 41731507289 | W4: =IF($A4="","",IFERROR(VLOOKUP($A4,AI_PF!$A:$CO,93,FALSE),"")) -> 12.543752 | X4: =IF($A4="","",COUNTIF(AI_PF!$A:$A,$A4)) -> 3 | Y4: =IF($A4="","",COUNTIF(LookThrough!$A:$A,J4)) -> 0
A5: BS00000021 | B5: =IF($A5="","",IFERROR(VLOOKUP($A5,AI_PF!$A:$D,4,FALSE),"")) -> 흥국 인프라 사모특별자산투자신탁 2호 (대구동부순환도로 리파이낸싱) | C5: =IF($A5="","",IFERROR(VLOOKUP($A5,AI_PF!$A:$G,7,FALSE),"")) -> BTO | D5: =IF($A5="","",IFERROR(VLOOKUP($A5,AI_PF!$A:$H,8,FALSE),"")) -> 도로 | E5: =IF($A5="","",IFERROR(VLOOKUP($A5,AI_PF!$A:$N,14,FALSE),"")) -> 수익증권 | F5: =IF($A5="","",IFERROR(VLOOKUP($A5,AI_PF!$A:$R,18,FALSE),"")) -> KRW | G5: =IF($A5="","",IFERROR(VLOOKUP($A5,AI_PF!$A:$T,20,FALSE),"")) -> 41085 | H5: =IF($A5="","",IFERROR(VLOOKUP($A5,AI_PF!$A:$V,22,FALSE),"")) -> 46562 | I5: =IF($A5="","",IFERROR(VLOOKUP($A5,AI_PF!$A:$EU,151,FALSE),"")) -> ~2016 | J5: =IF($A5="","",IFERROR(VLOOKUP($A5,AI_PF!$A:$C,3,FALSE),"")) -> 200000318 | K5: =IF($A5="","",IFERROR(VLOOKUP($A5,Data_Raw!$A:$G,2,FALSE),"")) -> Infrastructure | L5: =IF($A5="","",IFERROR(VLOOKUP($A5,Data_Raw!$A:$G,3,FALSE),"")) -> 흥국 인프라 사모특별자산투자신탁 2호 (대구동부순환도로 리파이낸싱) | M5: =IF($A5="","",IFERROR(VLOOKUP($A5,Data_Raw!$A:$G,4,FALSE),"")) -> 흥국자산운용 | N5: =IF($A5="","",IFERROR(VLOOKUP($A5,AI_PF!$A:$EU,29,FALSE),"")) -> 해당없음 | O5: =IF($A5="","",IFERROR(VLOOKUP($A5,Data_Raw!$A:$G,5,FALSE),"")) -> KOR | P5: =IF($A5="","",IFERROR(VLOOKUP($A5,Data_Raw!$A:$G,6,FALSE),"")) -> BTO | Q5: =IF($A5="","",IFERROR(VLOOKUP($A5,Data_Raw!$A:$G,7,FALSE),"")) -> Transportation | R5: =IF($A5="","",SUMIFS(AI_PF!$AP:$AP,AI_PF!$A:$A,$A5)) -> 90000000000 | S5: =IF($A5="","",SUMIFS(AI_PF!$AW:$AW,AI_PF!$A:$A,$A5)) -> 90000000000 | T5: =IF($A5="","",SUMIFS(AI_PF!$AZ:$AZ,AI_PF!$A:$A,$A5)) -> 85685503961 | U5: =IF($A5="","",SUMIFS(AI_PF!$CA:$CA,AI_PF!$A:$A,$A5)) -> 4351144467 | V5: =IF($A5="","",SUMIFS(AI_PF!$CE:$CE,AI_PF!$A:$A,$A5)) -> 4318302029 | W5: =IF($A5="","",IFERROR(VLOOKUP($A5,AI_PF!$A:$CO,93,FALSE),"")) -> 4.6826825 | X5: =IF($A5="","",COUNTIF(AI_PF!$A:$A,$A5)) -> 1 | Y5: =IF($A5="","",COUNTIF(LookThrough!$A:$A,J5)) -> 2
A6: BS00000029 | B6: =IF($A6="","",IFERROR(VLOOKUP($A6,AI_PF!$A:$D,4,FALSE),"")) -> 푸른김해지키미 | C6: =IF($A6="","",IFERROR(VLOOKUP($A6,AI_PF!$A:$G,7,FALSE),"")) -> BTL | D6: =IF($A6="","",IFERROR(VLOOKUP($A6,AI_PF!$A:$H,8,FALSE),"")) -> 하수관거 | E6: =IF($A6="","",IFERROR(VLOOKUP($A6,AI_PF!$A:$N,14,FALSE),"")) -> 대출 | F6: =IF($A6="","",IFERROR(VLOOKUP($A6,AI_PF!$A:$R,18,FALSE),"")) -> KRW | G6: =IF($A6="","",IFERROR(VLOOKUP($A6,AI_PF!$A:$T,20,FALSE),"")) -> 40289 | H6: =IF($A6="","",IFERROR(VLOOKUP($A6,AI_PF!$A:$V,22,FALSE),"")) -> 2958465 | I6: =IF($A6="","",IFERROR(VLOOKUP($A6,AI_PF!$A:$EU,151,FALSE),"")) -> ~2016 | J6: =IF($A6="","",IFERROR(VLOOKUP($A6,AI_PF!$A:$C,3,FALSE),"")) -> 6000000000209 | K6: =IF($A6="","",IFERROR(VLOOKUP($A6,Data_Raw!$A:$G,2,FALSE),"")) -> Infrastructure | L6: =IF($A6="","",IFERROR(VLOOKUP($A6,Data_Raw!$A:$G,3,FALSE),"")) -> 푸른김해지키미 | M6: =IF($A6="","",IFERROR(VLOOKUP($A6,Data_Raw!$A:$G,4,FALSE),"")) -> IBK기업은행 | N6: =IF($A6="","",IFERROR(VLOOKUP($A6,AI_PF!$A:$EU,29,FALSE),"")) -> 해당없음 | O6: =IF($A6="","",IFERROR(VLOOKUP($A6,Data_Raw!$A:$G,5,FALSE),"")) -> KOR | P6: =IF($A6="","",IFERROR(VLOOKUP($A6,Data_Raw!$A:$G,6,FALSE),"")) -> BTL | Q6: =IF($A6="","",IFERROR(VLOOKUP($A6,Data_Raw!$A:$G,7,FALSE),"")) -> Environmental | R6: =IF($A6="","",SUMIFS(AI_PF!$AP:$AP,AI_PF!$A:$A,$A6)) -> 20419035102 | S6: =IF($A6="","",SUMIFS(AI_PF!$AW:$AW,AI_PF!$A:$A,$A6)) -> 16023270000 | T6: =IF($A6="","",SUMIFS(AI_PF!$AZ:$AZ,AI_PF!$A:$A,$A6)) -> 12569126780 | U6: =IF($A6="","",SUMIFS(AI_PF!$CA:$CA,AI_PF!$A:$A,$A6)) -> 4888599289 | V6: =IF($A6="","",SUMIFS(AI_PF!$CE:$CE,AI_PF!$A:$A,$A6)) -> 4865152924 | W6: =IF($A6="","",IFERROR(VLOOKUP($A6,AI_PF!$A:$CO,93,FALSE),"")) -> 3.5150033 | X6: =IF($A6="","",COUNTIF(AI_PF!$A:$A,$A6)) -> 3 | Y6: =IF($A6="","",COUNTIF(LookThrough!$A:$A,J6)) -> 0
A7: BS00000030 | B7: =IF($A7="","",IFERROR(VLOOKUP($A7,AI_PF!$A:$D,4,FALSE),"")) -> 청정상주 | C7: =IF($A7="","",IFERROR(VLOOKUP($A7,AI_PF!$A:$G,7,FALSE),"")) -> BTL | D7: =IF($A7="","",IFERROR(VLOOKUP($A7,AI_PF!$A:$H,8,FALSE),"")) -> 하수관거 | E7: =IF($A7="","",IFERROR(VLOOKUP($A7,AI_PF!$A:$N,14,FALSE),"")) -> 대출 | F7: =IF($A7="","",IFERROR(VLOOKUP($A7,AI_PF!$A:$R,18,FALSE),"")) -> KRW | G7: =IF($A7="","",IFERROR(VLOOKUP($A7,AI_PF!$A:$T,20,FALSE),"")) -> 40239 | H7: =IF($A7="","",IFERROR(VLOOKUP($A7,AI_PF!$A:$V,22,FALSE),"")) -> 2958465 | I7: =IF($A7="","",IFERROR(VLOOKUP($A7,AI_PF!$A:$EU,151,FALSE),"")) -> ~2016 | J7: =IF($A7="","",IFERROR(VLOOKUP($A7,AI_PF!$A:$C,3,FALSE),"")) -> 6000000000250 | K7: =IF($A7="","",IFERROR(VLOOKUP($A7,Data_Raw!$A:$G,2,FALSE),"")) -> Infrastructure | L7: =IF($A7="","",IFERROR(VLOOKUP($A7,Data_Raw!$A:$G,3,FALSE),"")) -> 청정상주 | M7: =IF($A7="","",IFERROR(VLOOKUP($A7,Data_Raw!$A:$G,4,FALSE),"")) -> IBK기업은행 | N7: =IF($A7="","",IFERROR(VLOOKUP($A7,AI_PF!$A:$EU,29,FALSE),"")) -> 해당없음 | O7: =IF($A7="","",IFERROR(VLOOKUP($A7,Data_Raw!$A:$G,5,FALSE),"")) -> KOR | P7: =IF($A7="","",IFERROR(VLOOKUP($A7,Data_Raw!$A:$G,6,FALSE),"")) -> BTL | Q7: =IF($A7="","",IFERROR(VLOOKUP($A7,Data_Raw!$A:$G,7,FALSE),"")) -> Environmental | R7: =IF($A7="","",SUMIFS(AI_PF!$AP:$AP,AI_PF!$A:$A,$A7)) -> 16529000000 | S7: =IF($A7="","",SUMIFS(AI_PF!$AW:$AW,AI_PF!$A:$A,$A7)) -> 15180000000 | T7: =IF($A7="","",SUMIFS(AI_PF!$AZ:$AZ,AI_PF!$A:$A,$A7)) -> 11646513839 | U7: =IF($A7="","",SUMIFS(AI_PF!$CA:$CA,AI_PF!$A:$A,$A7)) -> 4857565965 | V7: =IF($A7="","",SUMIFS(AI_PF!$CE:$CE,AI_PF!$A:$A,$A7)) -> 4856859126 | W7: =IF($A7="","",IFERROR(VLOOKUP($A7,AI_PF!$A:$CO,93,FALSE),"")) -> 3.7224182 | X7: =IF($A7="","",COUNTIF(AI_PF!$A:$A,$A7)) -> 3 | Y7: =IF($A7="","",COUNTIF(LookThrough!$A:$A,J7)) -> 0
A8: BS00000034 | B8: =IF($A8="","",IFERROR(VLOOKUP($A8,AI_PF!$A:$D,4,FALSE),"")) -> 남양강진씨앤지 | C8: =IF($A8="","",IFERROR(VLOOKUP($A8,AI_PF!$A:$G,7,FALSE),"")) -> BTL | D8: =IF($A8="","",IFERROR(VLOOKUP($A8,AI_PF!$A:$H,8,FALSE),"")) -> 하수관거 | E8: =IF($A8="","",IFERROR(VLOOKUP($A8,AI_PF!$A:$N,14,FALSE),"")) -> 대출 | F8: =IF($A8="","",IFERROR(VLOOKUP($A8,AI_PF!$A:$R,18,FALSE),"")) -> KRW | G8: =IF($A8="","",IFERROR(VLOOKUP($A8,AI_PF!$A:$T,20,FALSE),"")) -> 40231 | H8: =IF($A8="","",IFERROR(VLOOKUP($A8,AI_PF!$A:$V,22,FALSE),"")) -> 2958465 | I8: =IF($A8="","",IFERROR(VLOOKUP($A8,AI_PF!$A:$EU,151,FALSE),"")) -> ~2016 | J8: =IF($A8="","",IFERROR(VLOOKUP($A8,AI_PF!$A:$C,3,FALSE),"")) -> 6000000000127 | K8: =IF($A8="","",IFERROR(VLOOKUP($A8,Data_Raw!$A:$G,2,FALSE),"")) -> Infrastructure | L8: =IF($A8="","",IFERROR(VLOOKUP($A8,Data_Raw!$A:$G,3,FALSE),"")) -> 남양강진씨앤지 | M8: =IF($A8="","",IFERROR(VLOOKUP($A8,Data_Raw!$A:$G,4,FALSE),"")) -> IBK기업은행 | N8: =IF($A8="","",IFERROR(VLOOKUP($A8,AI_PF!$A:$EU,29,FALSE),"")) -> 해당없음 | O8: =IF($A8="","",IFERROR(VLOOKUP($A8,Data_Raw!$A:$G,5,FALSE),"")) -> KOR | P8: =IF($A8="","",IFERROR(VLOOKUP($A8,Data_Raw!$A:$G,6,FALSE),"")) -> BTL | Q8: =IF($A8="","",IFERROR(VLOOKUP($A8,Data_Raw!$A:$G,7,FALSE),"")) -> Environmental | R8: =IF($A8="","",SUMIFS(AI_PF!$AP:$AP,AI_PF!$A:$A,$A8)) -> 8152918700 | S8: =IF($A8="","",SUMIFS(AI_PF!$AW:$AW,AI_PF!$A:$A,$A8)) -> 7632860000 | T8: =IF($A8="","",SUMIFS(AI_PF!$AZ:$AZ,AI_PF!$A:$A,$A8)) -> 5971592320 | U8: =IF($A8="","",SUMIFS(AI_PF!$CA:$CA,AI_PF!$A:$A,$A8)) -> 2181658700 | V8: =IF($A8="","",SUMIFS(AI_PF!$CE:$CE,AI_PF!$A:$A,$A8)) -> 2181326380 | W8: =IF($A8="","",IFERROR(VLOOKUP($A8,AI_PF!$A:$CO,93,FALSE),"")) -> 3.8884949 | X8: =IF($A8="","",COUNTIF(AI_PF!$A:$A,$A8)) -> 4 | Y8: =IF($A8="","",COUNTIF(LookThrough!$A:$A,J8)) -> 0
A9: BS00000035 | B9: =IF($A9="","",IFERROR(VLOOKUP($A9,AI_PF!$A:$D,4,FALSE),"")) -> 울산1지구 교육사업 | C9: =IF($A9="","",IFERROR(VLOOKUP($A9,AI_PF!$A:$G,7,FALSE),"")) -> BTL | D9: =IF($A9="","",IFERROR(VLOOKUP($A9,AI_PF!$A:$H,8,FALSE),"")) -> 교육시설 | E9: =IF($A9="","",IFERROR(VLOOKUP($A9,AI_PF!$A:$N,14,FALSE),"")) -> 대출 | F9: =IF($A9="","",IFERROR(VLOOKUP($A9,AI_PF!$A:$R,18,FALSE),"")) -> KRW | G9: =IF($A9="","",IFERROR(VLOOKUP($A9,AI_PF!$A:$T,20,FALSE),"")) -> 39668 | H9: =IF($A9="","",IFERROR(VLOOKUP($A9,AI_PF!$A:$V,22,FALSE),"")) -> 46310 | I9: =IF($A9="","",IFERROR(VLOOKUP($A9,AI_PF!$A:$EU,151,FALSE),"")) -> ~2016 | J9: =IF($A9="","",IFERROR(VLOOKUP($A9,AI_PF!$A:$C,3,FALSE),"")) -> 6000000000139 | K9: =IF($A9="","",IFERROR(VLOOKUP($A9,Data_Raw!$A:$G,2,FALSE),"")) -> Infrastructure | L9: =IF($A9="","",IFERROR(VLOOKUP($A9,Data_Raw!$A:$G,3,FALSE),"")) -> 울산1지구 교육사업 | M9: =IF($A9="","",IFERROR(VLOOKUP($A9,Data_Raw!$A:$G,4,FALSE),"")) -> IBK기업은행 | N9: =IF($A9="","",IFERROR(VLOOKUP($A9,AI_PF!$A:$EU,29,FALSE),"")) -> 해당없음 | O9: =IF($A9="","",IFERROR(VLOOKUP($A9,Data_Raw!$A:$G,5,FALSE),"")) -> KOR | P9: =IF($A9="","",IFERROR(VLOOKUP($A9,Data_Raw!$A:$G,6,FALSE),"")) -> BTL | Q9: =IF($A9="","",IFERROR(VLOOKUP($A9,Data_Raw!$A:$G,7,FALSE),"")) -> Social | R9: =IF($A9="","",SUMIFS(AI_PF!$AP:$AP,AI_PF!$A:$A,$A9)) -> 16584000000 | S9: =IF($A9="","",SUMIFS(AI_PF!$AW:$AW,AI_PF!$A:$A,$A9)) -> 16192000000 | T9: =IF($A9="","",SUMIFS(AI_PF!$AZ:$AZ,AI_PF!$A:$A,$A9)) -> 16176116078 | U9: =IF($A9="","",SUMIFS(AI_PF!$CA:$CA,AI_PF!$A:$A,$A9)) -> 15887100 | V9: =IF($A9="","",SUMIFS(AI_PF!$CE:$CE,AI_PF!$A:$A,$A9)) -> 15883922 | W9: =IF($A9="","",IFERROR(VLOOKUP($A9,AI_PF!$A:$CO,93,FALSE),"")) -> 4.3845332 | X9: =IF($A9="","",COUNTIF(AI_PF!$A:$A,$A9)) -> 10 | Y9: =IF($A9="","",COUNTIF(LookThrough!$A:$A,J9)) -> 0
A10: BS00000037 | B10: =IF($A10="","",IFERROR(VLOOKUP($A10,AI_PF!$A:$D,4,FALSE),"")) -> 울산3지구 교육사업 | C10: =IF($A10="","",IFERROR(VLOOKUP($A10,AI_PF!$A:$G,7,FALSE),"")) -> BTL | D10: =IF($A10="","",IFERROR(VLOOKUP($A10,AI_PF!$A:$H,8,FALSE),"")) -> 교육시설 | E10: =IF($A10="","",IFERROR(VLOOKUP($A10,AI_PF!$A:$N,14,FALSE),"")) -> 대출 | F10: =IF($A10="","",IFERROR(VLOOKUP($A10,AI_PF!$A:$R,18,FALSE),"")) -> KRW | G10: =IF($A10="","",IFERROR(VLOOKUP($A10,AI_PF!$A:$T,20,FALSE),"")) -> 39668 | H10: =IF($A10="","",IFERROR(VLOOKUP($A10,AI_PF!$A:$V,22,FALSE),"")) -> 46127 | I10: =IF($A10="","",IFERROR(VLOOKUP($A10,AI_PF!$A:$EU,151,FALSE),"")) -> ~2016 | J10: =IF($A10="","",IFERROR(VLOOKUP($A10,AI_PF!$A:$C,3,FALSE),"")) -> 6000000000098 | K10: =IF($A10="","",IFERROR(VLOOKUP($A10,Data_Raw!$A:$G,2,FALSE),"")) -> Infrastructure | L10: =IF($A10="","",IFERROR(VLOOKUP($A10,Data_Raw!$A:$G,3,FALSE),"")) -> 울산3지구 교육사업 | M10: =IF($A10="","",IFERROR(VLOOKUP($A10,Data_Raw!$A:$G,4,FALSE),"")) -> IBK기업은행 | N10: =IF($A10="","",IFERROR(VLOOKUP($A10,AI_PF!$A:$EU,29,FALSE),"")) -> 해당없음 | O10: =IF($A10="","",IFERROR(VLOOKUP($A10,Data_Raw!$A:$G,5,FALSE),"")) -> KOR | P10: =IF($A10="","",IFERROR(VLOOKUP($A10,Data_Raw!$A:$G,6,FALSE),"")) -> BTL | Q10: =IF($A10="","",IFERROR(VLOOKUP($A10,Data_Raw!$A:$G,7,FALSE),"")) -> Social | R10: =IF($A10="","",SUMIFS(AI_PF!$AP:$AP,AI_PF!$A:$A,$A10)) -> 9619000000 | S10: =IF($A10="","",SUMIFS(AI_PF!$AW:$AW,AI_PF!$A:$A,$A10)) -> 9619000000 | T10: =IF($A10="","",SUMIFS(AI_PF!$AZ:$AZ,AI_PF!$A:$A,$A10)) -> 9404493910 | U10: =IF($A10="","",SUMIFS(AI_PF!$CA:$CA,AI_PF!$A:$A,$A10)) -> 214549000 | V10: =IF($A10="","",SUMIFS(AI_PF!$CE:$CE,AI_PF!$A:$A,$A10)) -> 214506090 | W10: =IF($A10="","",IFERROR(VLOOKUP($A10,AI_PF!$A:$CO,93,FALSE),"")) -> 3.3200604 | X10: =IF($A10="","",COUNTIF(AI_PF!$A:$A,$A10)) -> 6 | Y10: =IF($A10="","",COUNTIF(LookThrough!$A:$A,J10)) -> 0
A11: BS00000039 | B11: =IF($A11="","",IFERROR(VLOOKUP($A11,AI_PF!$A:$D,4,FALSE),"")) -> 강원학교관리 | C11: =IF($A11="","",IFERROR(VLOOKUP($A11,AI_PF!$A:$G,7,FALSE),"")) -> BTL | D11: =IF($A11="","",IFERROR(VLOOKUP($A11,AI_PF!$A:$H,8,FALSE),"")) -> 교육시설 | E11: =IF($A11="","",IFERROR(VLOOKUP($A11,AI_PF!$A:$N,14,FALSE),"")) -> 대출 | F11: =IF($A11="","",IFERROR(VLOOKUP($A11,AI_PF!$A:$R,18,FALSE),"")) -> KRW | G11: =IF($A11="","",IFERROR(VLOOKUP($A11,AI_PF!$A:$T,20,FALSE),"")) -> 39631 | H11: =IF($A11="","",IFERROR(VLOOKUP($A11,AI_PF!$A:$V,22,FALSE),"")) -> 46042 | I11: =IF($A11="","",IFERROR(VLOOKUP($A11,AI_PF!$A:$EU,151,FALSE),"")) -> ~2016 | J11: =IF($A11="","",IFERROR(VLOOKUP($A11,AI_PF!$A:$C,3,FALSE),"")) -> 6000000000087 | K11: =IF($A11="","",IFERROR(VLOOKUP($A11,Data_Raw!$A:$G,2,FALSE),"")) -> Infrastructure | L11: =IF($A11="","",IFERROR(VLOOKUP($A11,Data_Raw!$A:$G,3,FALSE),"")) -> 강원학교관리 | M11: =IF($A11="","",IFERROR(VLOOKUP($A11,Data_Raw!$A:$G,4,FALSE),"")) -> IBK기업은행 | N11: =IF($A11="","",IFERROR(VLOOKUP($A11,AI_PF!$A:$EU,29,FALSE),"")) -> 해당없음 | O11: =IF($A11="","",IFERROR(VLOOKUP($A11,Data_Raw!$A:$G,5,FALSE),"")) -> KOR | P11: =IF($A11="","",IFERROR(VLOOKUP($A11,Data_Raw!$A:$G,6,FALSE),"")) -> BTL | Q11: =IF($A11="","",IFERROR(VLOOKUP($A11,Data_Raw!$A:$G,7,FALSE),"")) -> Social | R11: =IF($A11="","",SUMIFS(AI_PF!$AP:$AP,AI_PF!$A:$A,$A11)) -> 9179500000 | S11: =IF($A11="","",SUMIFS(AI_PF!$AW:$AW,AI_PF!$A:$A,$A11)) -> 8385600000 | T11: =IF($A11="","",SUMIFS(AI_PF!$AZ:$AZ,AI_PF!$A:$A,$A11)) -> 8226507650 | U11: =IF($A11="","",SUMIFS(AI_PF!$CA:$CA,AI_PF!$A:$A,$A11)) -> 159138800 | V11: =IF($A11="","",SUMIFS(AI_PF!$CE:$CE,AI_PF!$A:$A,$A11)) -> 159092350 | W11: =IF($A11="","",IFERROR(VLOOKUP($A11,AI_PF!$A:$CO,93,FALSE),"")) -> 4.5679509 | X11: =IF($A11="","",COUNTIF(AI_PF!$A:$A,$A11)) -> 18 | Y11: =IF($A11="","",COUNTIF(LookThrough!$A:$A,J11)) -> 0
A12: BS00000040 | B12: =IF($A12="","",IFERROR(VLOOKUP($A12,AI_PF!$A:$D,4,FALSE),"")) -> 푸른아산지키미 | C12: =IF($A12="","",IFERROR(VLOOKUP($A12,AI_PF!$A:$G,7,FALSE),"")) -> BTL | D12: =IF($A12="","",IFERROR(VLOOKUP($A12,AI_PF!$A:$H,8,FALSE),"")) -> 하수관거 | E12: =IF($A12="","",IFERROR(VLOOKUP($A12,AI_PF!$A:$N,14,FALSE),"")) -> 대출 | F12: =IF($A12="","",IFERROR(VLOOKUP($A12,AI_PF!$A:$R,18,FALSE),"")) -> KRW | G12: =IF($A12="","",IFERROR(VLOOKUP($A12,AI_PF!$A:$T,20,FALSE),"")) -> 40345 | H12: =IF($A12="","",IFERROR(VLOOKUP($A12,AI_PF!$A:$V,22,FALSE),"")) -> 2958465 | I12: =IF($A12="","",IFERROR(VLOOKUP($A12,AI_PF!$A:$EU,151,FALSE),"")) -> ~2016 | J12: =IF($A12="","",IFERROR(VLOOKUP($A12,AI_PF!$A:$C,3,FALSE),"")) -> 6000000000122 | K12: =IF($A12="","",IFERROR(VLOOKUP($A12,Data_Raw!$A:$G,2,FALSE),"")) -> Infrastructure | L12: =IF($A12="","",IFERROR(VLOOKUP($A12,Data_Raw!$A:$G,3,FALSE),"")) -> 푸른아산지키미 | M12: =IF($A12="","",IFERROR(VLOOKUP($A12,Data_Raw!$A:$G,4,FALSE),"")) -> IBK기업은행 | N12: =IF($A12="","",IFERROR(VLOOKUP($A12,AI_PF!$A:$EU,29,FALSE),"")) -> 해당없음 | O12: =IF($A12="","",IFERROR(VLOOKUP($A12,Data_Raw!$A:$G,5,FALSE),"")) -> KOR | P12: =IF($A12="","",IFERROR(VLOOKUP($A12,Data_Raw!$A:$G,6,FALSE),"")) -> BTL | Q12: =IF($A12="","",IFERROR(VLOOKUP($A12,Data_Raw!$A:$G,7,FALSE),"")) -> Environmental | R12: =IF($A12="","",SUMIFS(AI_PF!$AP:$AP,AI_PF!$A:$A,$A12)) -> 19530000000 | S12: =IF($A12="","",SUMIFS(AI_PF!$AW:$AW,AI_PF!$A:$A,$A12)) -> 17997000000 | T12: =IF($A12="","",SUMIFS(AI_PF!$AZ:$AZ,AI_PF!$A:$A,$A12)) -> 14020009557 | U12: =IF($A12="","",SUMIFS(AI_PF!$CA:$CA,AI_PF!$A:$A,$A12)) -> 5384898033 | V12: =IF($A12="","",SUMIFS(AI_PF!$CE:$CE,AI_PF!$A:$A,$A12)) -> 5384102476 | W12: =IF($A12="","",IFERROR(VLOOKUP($A12,AI_PF!$A:$CO,93,FALSE),"")) -> 3.619427 | X12: =IF($A12="","",COUNTIF(AI_PF!$A:$A,$A12)) -> 3 | Y12: =IF($A12="","",COUNTIF(LookThrough!$A:$A,J12)) -> 0
A13: BS00000041 | B13: =IF($A13="","",IFERROR(VLOOKUP($A13,AI_PF!$A:$D,4,FALSE),"")) -> 푸른여수지키미 | C13: =IF($A13="","",IFERROR(VLOOKUP($A13,AI_PF!$A:$G,7,FALSE),"")) -> BTL | D13: =IF($A13="","",IFERROR(VLOOKUP($A13,AI_PF!$A:$H,8,FALSE),"")) -> 하수관거 | E13: =IF($A13="","",IFERROR(VLOOKUP($A13,AI_PF!$A:$N,14,FALSE),"")) -> 대출 | F13: =IF($A13="","",IFERROR(VLOOKUP($A13,AI_PF!$A:$R,18,FALSE),"")) -> KRW | G13: =IF($A13="","",IFERROR(VLOOKUP($A13,AI_PF!$A:$T,20,FALSE),"")) -> 40267 | H13: =IF($A13="","",IFERROR(VLOOKUP($A13,AI_PF!$A:$V,22,FALSE),"")) -> 2958465 | I13: =IF($A13="","",IFERROR(VLOOKUP($A13,AI_PF!$A:$EU,151,FALSE),"")) -> ~2016 | J13: =IF($A13="","",IFERROR(VLOOKUP($A13,AI_PF!$A:$C,3,FALSE),"")) -> 6000000000151 | K13: =IF($A13="","",IFERROR(VLOOKUP($A13,Data_Raw!$A:$G,2,FALSE),"")) -> Infrastructure | L13: =IF($A13="","",IFERROR(VLOOKUP($A13,Data_Raw!$A:$G,3,FALSE),"")) -> 푸른여수지키미 | M13: =IF($A13="","",IFERROR(VLOOKUP($A13,Data_Raw!$A:$G,4,FALSE),"")) -> IBK기업은행 | N13: =IF($A13="","",IFERROR(VLOOKUP($A13,AI_PF!$A:$EU,29,FALSE),"")) -> 해당없음 | O13: =IF($A13="","",IFERROR(VLOOKUP($A13,Data_Raw!$A:$G,5,FALSE),"")) -> KOR | P13: =IF($A13="","",IFERROR(VLOOKUP($A13,Data_Raw!$A:$G,6,FALSE),"")) -> BTL | Q13: =IF($A13="","",IFERROR(VLOOKUP($A13,Data_Raw!$A:$G,7,FALSE),"")) -> Environmental | R13: =IF($A13="","",SUMIFS(AI_PF!$AP:$AP,AI_PF!$A:$A,$A13)) -> 11149330175 | S13: =IF($A13="","",SUMIFS(AI_PF!$AW:$AW,AI_PF!$A:$A,$A13)) -> 8735960000 | T13: =IF($A13="","",SUMIFS(AI_PF!$AZ:$AZ,AI_PF!$A:$A,$A13)) -> 6515210239 | U13: =IF($A13="","",SUMIFS(AI_PF!$CA:$CA,AI_PF!$A:$A,$A13)) -> 2879484175 | V13: =IF($A13="","",SUMIFS(AI_PF!$CE:$CE,AI_PF!$A:$A,$A13)) -> 2879039936 | W13: =IF($A13="","",IFERROR(VLOOKUP($A13,AI_PF!$A:$CO,93,FALSE),"")) -> 4.1665648 | X13: =IF($A13="","",COUNTIF(AI_PF!$A:$A,$A13)) -> 4 | Y13: =IF($A13="","",COUNTIF(LookThrough!$A:$A,J13)) -> 0
... A385: BS00001661 | B385: =IF($A385="","",IFERROR(VLOOKUP($A385,AI_PF!$A:$D,4,FALSE),"")) -> SIFC 담보대출 리파이낸싱(2026년) | C385: =IF($A385="","",IFERROR(VLOOKUP($A385,AI_PF!$A:$G,7,FALSE),"")) -> 수익형 | D385: =IF($A385="","",IFERROR(VLOOKUP($A385,AI_PF!$A:$H,8,FALSE),"")) -> 오피스 | E385: =IF($A385="","",IFERROR(VLOOKUP($A385,AI_PF!$A:$N,14,FALSE),"")) -> 대출 | F385: =IF($A385="","",IFERROR(VLOOKUP($A385,AI_PF!$A:$R,18,FALSE),"")) -> KRW | G385: =IF($A385="","",IFERROR(VLOOKUP($A385,AI_PF!$A:$T,20,FALSE),"")) -> 45747 | H385: =IF($A385="","",IFERROR(VLOOKUP($A385,AI_PF!$A:$V,22,FALSE),"")) -> 46843 | I385: =IF($A385="","",IFERROR(VLOOKUP($A385,AI_PF!$A:$EU,151,FALSE),"")) -> 2026 | J385: =IF($A385="","",IFERROR(VLOOKUP($A385,AI_PF!$A:$C,3,FALSE),"")) -> 6000000001330 | K385: =IF($A385="","",IFERROR(VLOOKUP($A385,Data_Raw!$A:$G,2,FALSE),"")) -> Real_Estate | L385: =IF($A385="","",IFERROR(VLOOKUP($A385,Data_Raw!$A:$G,3,FALSE),"")) -> SIFC 담보대출 리파이낸싱(2026년) | M385: =IF($A385="","",IFERROR(VLOOKUP($A385,Data_Raw!$A:$G,4,FALSE),"")) -> 국민은행 | N385: =IF($A385="","",IFERROR(VLOOKUP($A385,AI_PF!$A:$EU,29,FALSE),"")) -> 해당없음 | O385: =IF($A385="","",IFERROR(VLOOKUP($A385,Data_Raw!$A:$G,5,FALSE),"")) -> KOR | P385: =IF($A385="","",IFERROR(VLOOKUP($A385,Data_Raw!$A:$G,6,FALSE),"")) -> 담보대출 | Q385: =IF($A385="","",IFERROR(VLOOKUP($A385,Data_Raw!$A:$G,7,FALSE),"")) -> Office | R385: =IF($A385="","",SUMIFS(AI_PF!$AP:$AP,AI_PF!$A:$A,$A385)) -> 300000000000 | S385: =IF($A385="","",SUMIFS(AI_PF!$AW:$AW,AI_PF!$A:$A,$A385)) -> 300000000000 | T385: =IF($A385="","",SUMIFS(AI_PF!$AZ:$AZ,AI_PF!$A:$A,$A385)) -> 3346833601 | U385: =IF($A385="","",SUMIFS(AI_PF!$CA:$CA,AI_PF!$A:$A,$A385)) -> 300000000000 | V385: =IF($A385="","",SUMIFS(AI_PF!$CE:$CE,AI_PF!$A:$A,$A385)) -> 296653166399 | W385: =IF($A385="","",IFERROR(VLOOKUP($A385,AI_PF!$A:$CO,93,FALSE),"")) -> 4.5011406 | X385: =IF($A385="","",COUNTIF(AI_PF!$A:$A,$A385)) -> 4 | Y385: =IF($A385="","",COUNTIF(LookThrough!$A:$A,J385)) -> 0
B386: =IF($A386="","",IFERROR(VLOOKUP($A386,AI_PF!$A:$D,4,FALSE),"")) | C386: =IF($A386="","",IFERROR(VLOOKUP($A386,AI_PF!$A:$G,7,FALSE),"")) | D386: =IF($A386="","",IFERROR(VLOOKUP($A386,AI_PF!$A:$H,8,FALSE),"")) | E386: =IF($A386="","",IFERROR(VLOOKUP($A386,AI_PF!$A:$N,14,FALSE),"")) | F386: =IF($A386="","",IFERROR(VLOOKUP($A386,AI_PF!$A:$R,18,FALSE),"")) | G386: =IF($A386="","",IFERROR(VLOOKUP($A386,AI_PF!$A:$T,20,FALSE),"")) | H386: =IF($A386="","",IFERROR(VLOOKUP($A386,AI_PF!$A:$V,22,FALSE),"")) | I386: =IF($A386="","",IFERROR(VLOOKUP($A386,AI_PF!$A:$EU,151,FALSE),"")) | J386: =IF($A386="","",IFERROR(VLOOKUP($A386,AI_PF!$A:$C,3,FALSE),"")) | K386: =IF($A386="","",IFERROR(VLOOKUP($A386,Data_Raw!$A:$G,2,FALSE),"")) | L386: =IF($A386="","",IFERROR(VLOOKUP($A386,Data_Raw!$A:$G,3,FALSE),"")) | M386: =IF($A386="","",IFERROR(VLOOKUP($A386,Data_Raw!$A:$G,4,FALSE),"")) | N386: =IF($A386="","",IFERROR(VLOOKUP($A386,AI_PF!$A:$EU,29,FALSE),"")) | O386: =IF($A386="","",IFERROR(VLOOKUP($A386,Data_Raw!$A:$G,5,FALSE),"")) | P386: =IF($A386="","",IFERROR(VLOOKUP($A386,Data_Raw!$A:$G,6,FALSE),"")) | Q386: =IF($A386="","",IFERROR(VLOOKUP($A386,Data_Raw!$A:$G,7,FALSE),"")) | R386: =IF($A386="","",SUMIFS(AI_PF!$AP:$AP,AI_PF!$A:$A,$A386)) | S386: =IF($A386="","",SUMIFS(AI_PF!$AW:$AW,AI_PF!$A:$A,$A386)) | T386: =IF($A386="","",SUMIFS(AI_PF!$AZ:$AZ,AI_PF!$A:$A,$A386)) | U386: =IF($A386="","",SUMIFS(AI_PF!$CA:$CA,AI_PF!$A:$A,$A386)) | V386: =IF($A386="","",SUMIFS(AI_PF!$CE:$CE,AI_PF!$A:$A,$A386)) | W386: =IF($A386="","",IFERROR(VLOOKUP($A386,AI_PF!$A:$CO,93,FALSE),"")) | X386: =IF($A386="","",COUNTIF(AI_PF!$A:$A,$A386)) | Y386: =IF($A386="","",COUNTIF(LookThrough!$A:$A,J386))
B387: =IF($A387="","",IFERROR(VLOOKUP($A387,AI_PF!$A:$D,4,FALSE),"")) | C387: =IF($A387="","",IFERROR(VLOOKUP($A387,AI_PF!$A:$G,7,FALSE),"")) | D387: =IF($A387="","",IFERROR(VLOOKUP($A387,AI_PF!$A:$H,8,FALSE),"")) | E387: =IF($A387="","",IFERROR(VLOOKUP($A387,AI_PF!$A:$N,14,FALSE),"")) | F387: =IF($A387="","",IFERROR(VLOOKUP($A387,AI_PF!$A:$R,18,FALSE),"")) | G387: =IF($A387="","",IFERROR(VLOOKUP($A387,AI_PF!$A:$T,20,FALSE),"")) | H387: =IF($A387="","",IFERROR(VLOOKUP($A387,AI_PF!$A:$V,22,FALSE),"")) | I387: =IF($A387="","",IFERROR(VLOOKUP($A387,AI_PF!$A:$EU,151,FALSE),"")) | J387: =IF($A387="","",IFERROR(VLOOKUP($A387,AI_PF!$A:$C,3,FALSE),"")) | K387: =IF($A387="","",IFERROR(VLOOKUP($A387,Data_Raw!$A:$G,2,FALSE),"")) | L387: =IF($A387="","",IFERROR(VLOOKUP($A387,Data_Raw!$A:$G,3,FALSE),"")) | M387: =IF($A387="","",IFERROR(VLOOKUP($A387,Data_Raw!$A:$G,4,FALSE),"")) | N387: =IF($A387="","",IFERROR(VLOOKUP($A387,AI_PF!$A:$EU,29,FALSE),"")) | O387: =IF($A387="","",IFERROR(VLOOKUP($A387,Data_Raw!$A:$G,5,FALSE),"")) | P387: =IF($A387="","",IFERROR(VLOOKUP($A387,Data_Raw!$A:$G,6,FALSE),"")) | Q387: =IF($A387="","",IFERROR(VLOOKUP($A387,Data_Raw!$A:$G,7,FALSE),"")) | R387: =IF($A387="","",SUMIFS(AI_PF!$AP:$AP,AI_PF!$A:$A,$A387)) | S387: =IF($A387="","",SUMIFS(AI_PF!$AW:$AW,AI_PF!$A:$A,$A387)) | T387: =IF($A387="","",SUMIFS(AI_PF!$AZ:$AZ,AI_PF!$A:$A,$A387)) | U387: =IF($A387="","",SUMIFS(AI_PF!$CA:$CA,AI_PF!$A:$A,$A387)) | V387: =IF($A387="","",SUMIFS(AI_PF!$CE:$CE,AI_PF!$A:$A,$A387)) | W387: =IF($A387="","",IFERROR(VLOOKUP($A387,AI_PF!$A:$CO,93,FALSE),"")) | X387: =IF($A387="","",COUNTIF(AI_PF!$A:$A,$A387)) | Y387: =IF($A387="","",COUNTIF(LookThrough!$A:$A,J387))
B388: =IF($A388="","",IFERROR(VLOOKUP($A388,AI_PF!$A:$D,4,FALSE),"")) | C388: =IF($A388="","",IFERROR(VLOOKUP($A388,AI_PF!$A:$G,7,FALSE),"")) | D388: =IF($A388="","",IFERROR(VLOOKUP($A388,AI_PF!$A:$H,8,FALSE),"")) | E388: =IF($A388="","",IFERROR(VLOOKUP($A388,AI_PF!$A:$N,14,FALSE),"")) | F388: =IF($A388="","",IFERROR(VLOOKUP($A388,AI_PF!$A:$R,18,FALSE),"")) | G388: =IF($A388="","",IFERROR(VLOOKUP($A388,AI_PF!$A:$T,20,FALSE),"")) | H388: =IF($A388="","",IFERROR(VLOOKUP($A388,AI_PF!$A:$V,22,FALSE),"")) | I388: =IF($A388="","",IFERROR(VLOOKUP($A388,AI_PF!$A:$EU,151,FALSE),"")) | J388: =IF($A388="","",IFERROR(VLOOKUP($A388,AI_PF!$A:$C,3,FALSE),"")) | K388: =IF($A388="","",IFERROR(VLOOKUP($A388,Data_Raw!$A:$G,2,FALSE),"")) | L388: =IF($A388="","",IFERROR(VLOOKUP($A388,Data_Raw!$A:$G,3,FALSE),"")) | M388: =IF($A388="","",IFERROR(VLOOKUP($A388,Data_Raw!$A:$G,4,FALSE),"")) | N388: =IF($A388="","",IFERROR(VLOOKUP($A388,AI_PF!$A:$EU,29,FALSE),"")) | O388: =IF($A388="","",IFERROR(VLOOKUP($A388,Data_Raw!$A:$G,5,FALSE),"")) | P388: =IF($A388="","",IFERROR(VLOOKUP($A388,Data_Raw!$A:$G,6,FALSE),"")) | Q388: =IF($A388="","",IFERROR(VLOOKUP($A388,Data_Raw!$A:$G,7,FALSE),"")) | R388: =IF($A388="","",SUMIFS(AI_PF!$AP:$AP,AI_PF!$A:$A,$A388)) | S388: =IF($A388="","",SUMIFS(AI_PF!$AW:$AW,AI_PF!$A:$A,$A388)) | T388: =IF($A388="","",SUMIFS(AI_PF!$AZ:$AZ,AI_PF!$A:$A,$A388)) | U388: =IF($A388="","",SUMIFS(AI_PF!$CA:$CA,AI_PF!$A:$A,$A388)) | V388: =IF($A388="","",SUMIFS(AI_PF!$CE:$CE,AI_PF!$A:$A,$A388)) | W388: =IF($A388="","",IFERROR(VLOOKUP($A388,AI_PF!$A:$CO,93,FALSE),"")) | X388: =IF($A388="","",COUNTIF(AI_PF!$A:$A,$A388)) | Y388: =IF($A388="","",COUNTIF(LookThrough!$A:$A,J388))
B389: =IF($A389="","",IFERROR(VLOOKUP($A389,AI_PF!$A:$D,4,FALSE),"")) | C389: =IF($A389="","",IFERROR(VLOOKUP($A389,AI_PF!$A:$G,7,FALSE),"")) | D389: =IF($A389="","",IFERROR(VLOOKUP($A389,AI_PF!$A:$H,8,FALSE),"")) | E389: =IF($A389="","",IFERROR(VLOOKUP($A389,AI_PF!$A:$N,14,FALSE),"")) | F389: =IF($A389="","",IFERROR(VLOOKUP($A389,AI_PF!$A:$R,18,FALSE),"")) | G389: =IF($A389="","",IFERROR(VLOOKUP($A389,AI_PF!$A:$T,20,FALSE),"")) | H389: =IF($A389="","",IFERROR(VLOOKUP($A389,AI_PF!$A:$V,22,FALSE),"")) | I389: =IF($A389="","",IFERROR(VLOOKUP($A389,AI_PF!$A:$EU,151,FALSE),"")) | J389: =IF($A389="","",IFERROR(VLOOKUP($A389,AI_PF!$A:$C,3,FALSE),"")) | K389: =IF($A389="","",IFERROR(VLOOKUP($A389,Data_Raw!$A:$G,2,FALSE),"")) | L389: =IF($A389="","",IFERROR(VLOOKUP($A389,Data_Raw!$A:$G,3,FALSE),"")) | M389: =IF($A389="","",IFERROR(VLOOKUP($A389,Data_Raw!$A:$G,4,FALSE),"")) | N389: =IF($A389="","",IFERROR(VLOOKUP($A389,AI_PF!$A:$EU,29,FALSE),"")) | O389: =IF($A389="","",IFERROR(VLOOKUP($A389,Data_Raw!$A:$G,5,FALSE),"")) | P389: =IF($A389="","",IFERROR(VLOOKUP($A389,Data_Raw!$A:$G,6,FALSE),"")) | Q389: =IF($A389="","",IFERROR(VLOOKUP($A389,Data_Raw!$A:$G,7,FALSE),"")) | R389: =IF($A389="","",SUMIFS(AI_PF!$AP:$AP,AI_PF!$A:$A,$A389)) | S389: =IF($A389="","",SUMIFS(AI_PF!$AW:$AW,AI_PF!$A:$A,$A389)) | T389: =IF($A389="","",SUMIFS(AI_PF!$AZ:$AZ,AI_PF!$A:$A,$A389)) | U389: =IF($A389="","",SUMIFS(AI_PF!$CA:$CA,AI_PF!$A:$A,$A389)) | V389: =IF($A389="","",SUMIFS(AI_PF!$CE:$CE,AI_PF!$A:$A,$A389)) | W389: =IF($A389="","",IFERROR(VLOOKUP($A389,AI_PF!$A:$CO,93,FALSE),"")) | X389: =IF($A389="","",COUNTIF(AI_PF!$A:$A,$A389)) | Y389: =IF($A389="","",COUNTIF(LookThrough!$A:$A,J389))
B390: =IF($A390="","",IFERROR(VLOOKUP($A390,AI_PF!$A:$D,4,FALSE),"")) | C390: =IF($A390="","",IFERROR(VLOOKUP($A390,AI_PF!$A:$G,7,FALSE),"")) | D390: =IF($A390="","",IFERROR(VLOOKUP($A390,AI_PF!$A:$H,8,FALSE),"")) | E390: =IF($A390="","",IFERROR(VLOOKUP($A390,AI_PF!$A:$N,14,FALSE),"")) | F390: =IF($A390="","",IFERROR(VLOOKUP($A390,AI_PF!$A:$R,18,FALSE),"")) | G390: =IF($A390="","",IFERROR(VLOOKUP($A390,AI_PF!$A:$T,20,FALSE),"")) | H390: =IF($A390="","",IFERROR(VLOOKUP($A390,AI_PF!$A:$V,22,FALSE),"")) | I390: =IF($A390="","",IFERROR(VLOOKUP($A390,AI_PF!$A:$EU,151,FALSE),"")) | J390: =IF($A390="","",IFERROR(VLOOKUP($A390,AI_PF!$A:$C,3,FALSE),"")) | K390: =IF($A390="","",IFERROR(VLOOKUP($A390,Data_Raw!$A:$G,2,FALSE),"")) | L390: =IF($A390="","",IFERROR(VLOOKUP($A390,Data_Raw!$A:$G,3,FALSE),"")) | M390: =IF($A390="","",IFERROR(VLOOKUP($A390,Data_Raw!$A:$G,4,FALSE),"")) | N390: =IF($A390="","",IFERROR(VLOOKUP($A390,AI_PF!$A:$EU,29,FALSE),"")) | O390: =IF($A390="","",IFERROR(VLOOKUP($A390,Data_Raw!$A:$G,5,FALSE),"")) | P390: =IF($A390="","",IFERROR(VLOOKUP($A390,Data_Raw!$A:$G,6,FALSE),"")) | Q390: =IF($A390="","",IFERROR(VLOOKUP($A390,Data_Raw!$A:$G,7,FALSE),"")) | R390: =IF($A390="","",SUMIFS(AI_PF!$AP:$AP,AI_PF!$A:$A,$A390)) | S390: =IF($A390="","",SUMIFS(AI_PF!$AW:$AW,AI_PF!$A:$A,$A390)) | T390: =IF($A390="","",SUMIFS(AI_PF!$AZ:$AZ,AI_PF!$A:$A,$A390)) | U390: =IF($A390="","",SUMIFS(AI_PF!$CA:$CA,AI_PF!$A:$A,$A390)) | V390: =IF($A390="","",SUMIFS(AI_PF!$CE:$CE,AI_PF!$A:$A,$A390)) | W390: =IF($A390="","",IFERROR(VLOOKUP($A390,AI_PF!$A:$CO,93,FALSE),"")) | X390: =IF($A390="","",COUNTIF(AI_PF!$A:$A,$A390)) | Y390: =IF($A390="","",COUNTIF(LookThrough!$A:$A,J390))
B391: =IF($A391="","",IFERROR(VLOOKUP($A391,AI_PF!$A:$D,4,FALSE),"")) | C391: =IF($A391="","",IFERROR(VLOOKUP($A391,AI_PF!$A:$G,7,FALSE),"")) | D391: =IF($A391="","",IFERROR(VLOOKUP($A391,AI_PF!$A:$H,8,FALSE),"")) | E391: =IF($A391="","",IFERROR(VLOOKUP($A391,AI_PF!$A:$N,14,FALSE),"")) | F391: =IF($A391="","",IFERROR(VLOOKUP($A391,AI_PF!$A:$R,18,FALSE),"")) | G391: =IF($A391="","",IFERROR(VLOOKUP($A391,AI_PF!$A:$T,20,FALSE),"")) | H391: =IF($A391="","",IFERROR(VLOOKUP($A391,AI_PF!$A:$V,22,FALSE),"")) | I391: =IF($A391="","",IFERROR(VLOOKUP($A391,AI_PF!$A:$EU,151,FALSE),"")) | J391: =IF($A391="","",IFERROR(VLOOKUP($A391,AI_PF!$A:$C,3,FALSE),"")) | K391: =IF($A391="","",IFERROR(VLOOKUP($A391,Data_Raw!$A:$G,2,FALSE),"")) | L391: =IF($A391="","",IFERROR(VLOOKUP($A391,Data_Raw!$A:$G,3,FALSE),"")) | M391: =IF($A391="","",IFERROR(VLOOKUP($A391,Data_Raw!$A:$G,4,FALSE),"")) | N391: =IF($A391="","",IFERROR(VLOOKUP($A391,AI_PF!$A:$EU,29,FALSE),"")) | O391: =IF($A391="","",IFERROR(VLOOKUP($A391,Data_Raw!$A:$G,5,FALSE),"")) | P391: =IF($A391="","",IFERROR(VLOOKUP($A391,Data_Raw!$A:$G,6,FALSE),"")) | Q391: =IF($A391="","",IFERROR(VLOOKUP($A391,Data_Raw!$A:$G,7,FALSE),"")) | R391: =IF($A391="","",SUMIFS(AI_PF!$AP:$AP,AI_PF!$A:$A,$A391)) | S391: =IF($A391="","",SUMIFS(AI_PF!$AW:$AW,AI_PF!$A:$A,$A391)) | T391: =IF($A391="","",SUMIFS(AI_PF!$AZ:$AZ,AI_PF!$A:$A,$A391)) | U391: =IF($A391="","",SUMIFS(AI_PF!$CA:$CA,AI_PF!$A:$A,$A391)) | V391: =IF($A391="","",SUMIFS(AI_PF!$CE:$CE,AI_PF!$A:$A,$A391)) | W391: =IF($A391="","",IFERROR(VLOOKUP($A391,AI_PF!$A:$CO,93,FALSE),"")) | X391: =IF($A391="","",COUNTIF(AI_PF!$A:$A,$A391)) | Y391: =IF($A391="","",COUNTIF(LookThrough!$A:$A,J391))
B392: =IF($A392="","",IFERROR(VLOOKUP($A392,AI_PF!$A:$D,4,FALSE),"")) | C392: =IF($A392="","",IFERROR(VLOOKUP($A392,AI_PF!$A:$G,7,FALSE),"")) | D392: =IF($A392="","",IFERROR(VLOOKUP($A392,AI_PF!$A:$H,8,FALSE),"")) | E392: =IF($A392="","",IFERROR(VLOOKUP($A392,AI_PF!$A:$N,14,FALSE),"")) | F392: =IF($A392="","",IFERROR(VLOOKUP($A392,AI_PF!$A:$R,18,FALSE),"")) | G392: =IF($A392="","",IFERROR(VLOOKUP($A392,AI_PF!$A:$T,20,FALSE),"")) | H392: =IF($A392="","",IFERROR(VLOOKUP($A392,AI_PF!$A:$V,22,FALSE),"")) | I392: =IF($A392="","",IFERROR(VLOOKUP($A392,AI_PF!$A:$EU,151,FALSE),"")) | J392: =IF($A392="","",IFERROR(VLOOKUP($A392,AI_PF!$A:$C,3,FALSE),"")) | K392: =IF($A392="","",IFERROR(VLOOKUP($A392,Data_Raw!$A:$G,2,FALSE),"")) | L392: =IF($A392="","",IFERROR(VLOOKUP($A392,Data_Raw!$A:$G,3,FALSE),"")) | M392: =IF($A392="","",IFERROR(VLOOKUP($A392,Data_Raw!$A:$G,4,FALSE),"")) | N392: =IF($A392="","",IFERROR(VLOOKUP($A392,AI_PF!$A:$EU,29,FALSE),"")) | O392: =IF($A392="","",IFERROR(VLOOKUP($A392,Data_Raw!$A:$G,5,FALSE),"")) | P392: =IF($A392="","",IFERROR(VLOOKUP($A392,Data_Raw!$A:$G,6,FALSE),"")) | Q392: =IF($A392="","",IFERROR(VLOOKUP($A392,Data_Raw!$A:$G,7,FALSE),"")) | R392: =IF($A392="","",SUMIFS(AI_PF!$AP:$AP,AI_PF!$A:$A,$A392)) | S392: =IF($A392="","",SUMIFS(AI_PF!$AW:$AW,AI_PF!$A:$A,$A392)) | T392: =IF($A392="","",SUMIFS(AI_PF!$AZ:$AZ,AI_PF!$A:$A,$A392)) | U392: =IF($A392="","",SUMIFS(AI_PF!$CA:$CA,AI_PF!$A:$A,$A392)) | V392: =IF($A392="","",SUMIFS(AI_PF!$CE:$CE,AI_PF!$A:$A,$A392)) | W392: =IF($A392="","",IFERROR(VLOOKUP($A392,AI_PF!$A:$CO,93,FALSE),"")) | X392: =IF($A392="","",COUNTIF(AI_PF!$A:$A,$A392)) | Y392: =IF($A392="","",COUNTIF(LookThrough!$A:$A,J392))
B393: =IF($A393="","",IFERROR(VLOOKUP($A393,AI_PF!$A:$D,4,FALSE),"")) | C393: =IF($A393="","",IFERROR(VLOOKUP($A393,AI_PF!$A:$G,7,FALSE),"")) | D393: =IF($A393="","",IFERROR(VLOOKUP($A393,AI_PF!$A:$H,8,FALSE),"")) | E393: =IF($A393="","",IFERROR(VLOOKUP($A393,AI_PF!$A:$N,14,FALSE),"")) | F393: =IF($A393="","",IFERROR(VLOOKUP($A393,AI_PF!$A:$R,18,FALSE),"")) | G393: =IF($A393="","",IFERROR(VLOOKUP($A393,AI_PF!$A:$T,20,FALSE),"")) | H393: =IF($A393="","",IFERROR(VLOOKUP($A393,AI_PF!$A:$V,22,FALSE),"")) | I393: =IF($A393="","",IFERROR(VLOOKUP($A393,AI_PF!$A:$EU,151,FALSE),"")) | J393: =IF($A393="","",IFERROR(VLOOKUP($A393,AI_PF!$A:$C,3,FALSE),"")) | K393: =IF($A393="","",IFERROR(VLOOKUP($A393,Data_Raw!$A:$G,2,FALSE),"")) | L393: =IF($A393="","",IFERROR(VLOOKUP($A393,Data_Raw!$A:$G,3,FALSE),"")) | M393: =IF($A393="","",IFERROR(VLOOKUP($A393,Data_Raw!$A:$G,4,FALSE),"")) | N393: =IF($A393="","",IFERROR(VLOOKUP($A393,AI_PF!$A:$EU,29,FALSE),"")) | O393: =IF($A393="","",IFERROR(VLOOKUP($A393,Data_Raw!$A:$G,5,FALSE),"")) | P393: =IF($A393="","",IFERROR(VLOOKUP($A393,Data_Raw!$A:$G,6,FALSE),"")) | Q393: =IF($A393="","",IFERROR(VLOOKUP($A393,Data_Raw!$A:$G,7,FALSE),"")) | R393: =IF($A393="","",SUMIFS(AI_PF!$AP:$AP,AI_PF!$A:$A,$A393)) | S393: =IF($A393="","",SUMIFS(AI_PF!$AW:$AW,AI_PF!$A:$A,$A393)) | T393: =IF($A393="","",SUMIFS(AI_PF!$AZ:$AZ,AI_PF!$A:$A,$A393)) | U393: =IF($A393="","",SUMIFS(AI_PF!$CA:$CA,AI_PF!$A:$A,$A393)) | V393: =IF($A393="","",SUMIFS(AI_PF!$CE:$CE,AI_PF!$A:$A,$A393)) | W393: =IF($A393="","",IFERROR(VLOOKUP($A393,AI_PF!$A:$CO,93,FALSE),"")) | X393: =IF($A393="","",COUNTIF(AI_PF!$A:$A,$A393)) | Y393: =IF($A393="","",COUNTIF(LookThrough!$A:$A,J393))
B394: =IF($A394="","",IFERROR(VLOOKUP($A394,AI_PF!$A:$D,4,FALSE),"")) | C394: =IF($A394="","",IFERROR(VLOOKUP($A394,AI_PF!$A:$G,7,FALSE),"")) | D394: =IF($A394="","",IFERROR(VLOOKUP($A394,AI_PF!$A:$H,8,FALSE),"")) | E394: =IF($A394="","",IFERROR(VLOOKUP($A394,AI_PF!$A:$N,14,FALSE),"")) | F394: =IF($A394="","",IFERROR(VLOOKUP($A394,AI_PF!$A:$R,18,FALSE),"")) | G394: =IF($A394="","",IFERROR(VLOOKUP($A394,AI_PF!$A:$T,20,FALSE),"")) | H394: =IF($A394="","",IFERROR(VLOOKUP($A394,AI_PF!$A:$V,22,FALSE),"")) | I394: =IF($A394="","",IFERROR(VLOOKUP($A394,AI_PF!$A:$EU,151,FALSE),"")) | J394: =IF($A394="","",IFERROR(VLOOKUP($A394,AI_PF!$A:$C,3,FALSE),"")) | K394: =IF($A394="","",IFERROR(VLOOKUP($A394,Data_Raw!$A:$G,2,FALSE),"")) | L394: =IF($A394="","",IFERROR(VLOOKUP($A394,Data_Raw!$A:$G,3,FALSE),"")) | M394: =IF($A394="","",IFERROR(VLOOKUP($A394,Data_Raw!$A:$G,4,FALSE),"")) | N394: =IF($A394="","",IFERROR(VLOOKUP($A394,AI_PF!$A:$EU,29,FALSE),"")) | O394: =IF($A394="","",IFERROR(VLOOKUP($A394,Data_Raw!$A:$G,5,FALSE),"")) | P394: =IF($A394="","",IFERROR(VLOOKUP($A394,Data_Raw!$A:$G,6,FALSE),"")) | Q394: =IF($A394="","",IFERROR(VLOOKUP($A394,Data_Raw!$A:$G,7,FALSE),"")) | R394: =IF($A394="","",SUMIFS(AI_PF!$AP:$AP,AI_PF!$A:$A,$A394)) | S394: =IF($A394="","",SUMIFS(AI_PF!$AW:$AW,AI_PF!$A:$A,$A394)) | T394: =IF($A394="","",SUMIFS(AI_PF!$AZ:$AZ,AI_PF!$A:$A,$A394)) | U394: =IF($A394="","",SUMIFS(AI_PF!$CA:$CA,AI_PF!$A:$A,$A394)) | V394: =IF($A394="","",SUMIFS(AI_PF!$CE:$CE,AI_PF!$A:$A,$A394)) | W394: =IF($A394="","",IFERROR(VLOOKUP($A394,AI_PF!$A:$CO,93,FALSE),"")) | X394: =IF($A394="","",COUNTIF(AI_PF!$A:$A,$A394)) | Y394: =IF($A394="","",COUNTIF(LookThrough!$A:$A,J394))
B395: =IF($A395="","",IFERROR(VLOOKUP($A395,AI_PF!$A:$D,4,FALSE),"")) | C395: =IF($A395="","",IFERROR(VLOOKUP($A395,AI_PF!$A:$G,7,FALSE),"")) | D395: =IF($A395="","",IFERROR(VLOOKUP($A395,AI_PF!$A:$H,8,FALSE),"")) | E395: =IF($A395="","",IFERROR(VLOOKUP($A395,AI_PF!$A:$N,14,FALSE),"")) | F395: =IF($A395="","",IFERROR(VLOOKUP($A395,AI_PF!$A:$R,18,FALSE),"")) | G395: =IF($A395="","",IFERROR(VLOOKUP($A395,AI_PF!$A:$T,20,FALSE),"")) | H395: =IF($A395="","",IFERROR(VLOOKUP($A395,AI_PF!$A:$V,22,FALSE),"")) | I395: =IF($A395="","",IFERROR(VLOOKUP($A395,AI_PF!$A:$EU,151,FALSE),"")) | J395: =IF($A395="","",IFERROR(VLOOKUP($A395,AI_PF!$A:$C,3,FALSE),"")) | K395: =IF($A395="","",IFERROR(VLOOKUP($A395,Data_Raw!$A:$G,2,FALSE),"")) | L395: =IF($A395="","",IFERROR(VLOOKUP($A395,Data_Raw!$A:$G,3,FALSE),"")) | M395: =IF($A395="","",IFERROR(VLOOKUP($A395,Data_Raw!$A:$G,4,FALSE),"")) | N395: =IF($A395="","",IFERROR(VLOOKUP($A395,AI_PF!$A:$EU,29,FALSE),"")) | O395: =IF($A395="","",IFERROR(VLOOKUP($A395,Data_Raw!$A:$G,5,FALSE),"")) | P395: =IF($A395="","",IFERROR(VLOOKUP($A395,Data_Raw!$A:$G,6,FALSE),"")) | Q395: =IF($A395="","",IFERROR(VLOOKUP($A395,Data_Raw!$A:$G,7,FALSE),"")) | R395: =IF($A395="","",SUMIFS(AI_PF!$AP:$AP,AI_PF!$A:$A,$A395)) | S395: =IF($A395="","",SUMIFS(AI_PF!$AW:$AW,AI_PF!$A:$A,$A395)) | T395: =IF($A395="","",SUMIFS(AI_PF!$AZ:$AZ,AI_PF!$A:$A,$A395)) | U395: =IF($A395="","",SUMIFS(AI_PF!$CA:$CA,AI_PF!$A:$A,$A395)) | V395: =IF($A395="","",SUMIFS(AI_PF!$CE:$CE,AI_PF!$A:$A,$A395)) | W395: =IF($A395="","",IFERROR(VLOOKUP($A395,AI_PF!$A:$CO,93,FALSE),"")) | X395: =IF($A395="","",COUNTIF(AI_PF!$A:$A,$A395)) | Y395: =IF($A395="","",COUNTIF(LookThrough!$A:$A,J395))
B396: =IF($A396="","",IFERROR(VLOOKUP($A396,AI_PF!$A:$D,4,FALSE),"")) | C396: =IF($A396="","",IFERROR(VLOOKUP($A396,AI_PF!$A:$G,7,FALSE),"")) | D396: =IF($A396="","",IFERROR(VLOOKUP($A396,AI_PF!$A:$H,8,FALSE),"")) | E396: =IF($A396="","",IFERROR(VLOOKUP($A396,AI_PF!$A:$N,14,FALSE),"")) | F396: =IF($A396="","",IFERROR(VLOOKUP($A396,AI_PF!$A:$R,18,FALSE),"")) | G396: =IF($A396="","",IFERROR(VLOOKUP($A396,AI_PF!$A:$T,20,FALSE),"")) | H396: =IF($A396="","",IFERROR(VLOOKUP($A396,AI_PF!$A:$V,22,FALSE),"")) | I396: =IF($A396="","",IFERROR(VLOOKUP($A396,AI_PF!$A:$EU,151,FALSE),"")) | J396: =IF($A396="","",IFERROR(VLOOKUP($A396,AI_PF!$A:$C,3,FALSE),"")) | K396: =IF($A396="","",IFERROR(VLOOKUP($A396,Data_Raw!$A:$G,2,FALSE),"")) | L396: =IF($A396="","",IFERROR(VLOOKUP($A396,Data_Raw!$A:$G,3,FALSE),"")) | M396: =IF($A396="","",IFERROR(VLOOKUP($A396,Data_Raw!$A:$G,4,FALSE),"")) | N396: =IF($A396="","",IFERROR(VLOOKUP($A396,AI_PF!$A:$EU,29,FALSE),"")) | O396: =IF($A396="","",IFERROR(VLOOKUP($A396,Data_Raw!$A:$G,5,FALSE),"")) | P396: =IF($A396="","",IFERROR(VLOOKUP($A396,Data_Raw!$A:$G,6,FALSE),"")) | Q396: =IF($A396="","",IFERROR(VLOOKUP($A396,Data_Raw!$A:$G,7,FALSE),"")) | R396: =IF($A396="","",SUMIFS(AI_PF!$AP:$AP,AI_PF!$A:$A,$A396)) | S396: =IF($A396="","",SUMIFS(AI_PF!$AW:$AW,AI_PF!$A:$A,$A396)) | T396: =IF($A396="","",SUMIFS(AI_PF!$AZ:$AZ,AI_PF!$A:$A,$A396)) | U396: =IF($A396="","",SUMIFS(AI_PF!$CA:$CA,AI_PF!$A:$A,$A396)) | V396: =IF($A396="","",SUMIFS(AI_PF!$CE:$CE,AI_PF!$A:$A,$A396)) | W396: =IF($A396="","",IFERROR(VLOOKUP($A396,AI_PF!$A:$CO,93,FALSE),"")) | X396: =IF($A396="","",COUNTIF(AI_PF!$A:$A,$A396)) | Y396: =IF($A396="","",COUNTIF(LookThrough!$A:$A,J396))
B397: =IF($A397="","",IFERROR(VLOOKUP($A397,AI_PF!$A:$D,4,FALSE),"")) | C397: =IF($A397="","",IFERROR(VLOOKUP($A397,AI_PF!$A:$G,7,FALSE),"")) | D397: =IF($A397="","",IFERROR(VLOOKUP($A397,AI_PF!$A:$H,8,FALSE),"")) | E397: =IF($A397="","",IFERROR(VLOOKUP($A397,AI_PF!$A:$N,14,FALSE),"")) | F397: =IF($A397="","",IFERROR(VLOOKUP($A397,AI_PF!$A:$R,18,FALSE),"")) | G397: =IF($A397="","",IFERROR(VLOOKUP($A397,AI_PF!$A:$T,20,FALSE),"")) | H397: =IF($A397="","",IFERROR(VLOOKUP($A397,AI_PF!$A:$V,22,FALSE),"")) | I397: =IF($A397="","",IFERROR(VLOOKUP($A397,AI_PF!$A:$EU,151,FALSE),"")) | J397: =IF($A397="","",IFERROR(VLOOKUP($A397,AI_PF!$A:$C,3,FALSE),"")) | K397: =IF($A397="","",IFERROR(VLOOKUP($A397,Data_Raw!$A:$G,2,FALSE),"")) | L397: =IF($A397="","",IFERROR(VLOOKUP($A397,Data_Raw!$A:$G,3,FALSE),"")) | M397: =IF($A397="","",IFERROR(VLOOKUP($A397,Data_Raw!$A:$G,4,FALSE),"")) | N397: =IF($A397="","",IFERROR(VLOOKUP($A397,AI_PF!$A:$EU,29,FALSE),"")) | O397: =IF($A397="","",IFERROR(VLOOKUP($A397,Data_Raw!$A:$G,5,FALSE),"")) | P397: =IF($A397="","",IFERROR(VLOOKUP($A397,Data_Raw!$A:$G,6,FALSE),"")) | Q397: =IF($A397="","",IFERROR(VLOOKUP($A397,Data_Raw!$A:$G,7,FALSE),"")) | R397: =IF($A397="","",SUMIFS(AI_PF!$AP:$AP,AI_PF!$A:$A,$A397)) | S397: =IF($A397="","",SUMIFS(AI_PF!$AW:$AW,AI_PF!$A:$A,$A397)) | T397: =IF($A397="","",SUMIFS(AI_PF!$AZ:$AZ,AI_PF!$A:$A,$A397)) | U397: =IF($A397="","",SUMIFS(AI_PF!$CA:$CA,AI_PF!$A:$A,$A397)) | V397: =IF($A397="","",SUMIFS(AI_PF!$CE:$CE,AI_PF!$A:$A,$A397)) | W397: =IF($A397="","",IFERROR(VLOOKUP($A397,AI_PF!$A:$CO,93,FALSE),"")) | X397: =IF($A397="","",COUNTIF(AI_PF!$A:$A,$A397)) | Y397: =IF($A397="","",COUNTIF(LookThrough!$A:$A,J397))
... B524: =IF($A524="","",IFERROR(VLOOKUP($A524,AI_PF!$A:$D,4,FALSE),"")) | C524: =IF($A524="","",IFERROR(VLOOKUP($A524,AI_PF!$A:$G,7,FALSE),"")) | D524: =IF($A524="","",IFERROR(VLOOKUP($A524,AI_PF!$A:$H,8,FALSE),"")) | E524: =IF($A524="","",IFERROR(VLOOKUP($A524,AI_PF!$A:$N,14,FALSE),"")) | F524: =IF($A524="","",IFERROR(VLOOKUP($A524,AI_PF!$A:$R,18,FALSE),"")) | G524: =IF($A524="","",IFERROR(VLOOKUP($A524,AI_PF!$A:$T,20,FALSE),"")) | H524: =IF($A524="","",IFERROR(VLOOKUP($A524,AI_PF!$A:$V,22,FALSE),"")) | I524: =IF($A524="","",IFERROR(VLOOKUP($A524,AI_PF!$A:$EU,151,FALSE),"")) | J524: =IF($A524="","",IFERROR(VLOOKUP($A524,AI_PF!$A:$C,3,FALSE),"")) | K524: =IF($A524="","",IFERROR(VLOOKUP($A524,Data_Raw!$A:$G,2,FALSE),"")) | L524: =IF($A524="","",IFERROR(VLOOKUP($A524,Data_Raw!$A:$G,3,FALSE),"")) | M524: =IF($A524="","",IFERROR(VLOOKUP($A524,Data_Raw!$A:$G,4,FALSE),"")) | N524: =IF($A524="","",IFERROR(VLOOKUP($A524,AI_PF!$A:$EU,29,FALSE),"")) | O524: =IF($A524="","",IFERROR(VLOOKUP($A524,Data_Raw!$A:$G,5,FALSE),"")) | P524: =IF($A524="","",IFERROR(VLOOKUP($A524,Data_Raw!$A:$G,6,FALSE),"")) | Q524: =IF($A524="","",IFERROR(VLOOKUP($A524,Data_Raw!$A:$G,7,FALSE),"")) | R524: =IF($A524="","",SUMIFS(AI_PF!$AP:$AP,AI_PF!$A:$A,$A524)) | S524: =IF($A524="","",SUMIFS(AI_PF!$AW:$AW,AI_PF!$A:$A,$A524)) | T524: =IF($A524="","",SUMIFS(AI_PF!$AZ:$AZ,AI_PF!$A:$A,$A524)) | U524: =IF($A524="","",SUMIFS(AI_PF!$CA:$CA,AI_PF!$A:$A,$A524)) | V524: =IF($A524="","",SUMIFS(AI_PF!$CE:$CE,AI_PF!$A:$A,$A524)) | W524: =IF($A524="","",IFERROR(VLOOKUP($A524,AI_PF!$A:$CO,93,FALSE),"")) | X524: =IF($A524="","",COUNTIF(AI_PF!$A:$A,$A524)) | Y524: =IF($A524="","",COUNTIF(LookThrough!$A:$A,J524))
A525: BS00001626 | B525: =IF($A525="","",IFERROR(VLOOKUP($A525,AI_PF!$A:$D,4,FALSE),"")) -> 이지스글로벌일반사모부동산투자신탁576호(재간접형) | C525: =IF($A525="","",IFERROR(VLOOKUP($A525,AI_PF!$A:$G,7,FALSE),"")) -> 수익형 | D525: =IF($A525="","",IFERROR(VLOOKUP($A525,AI_PF!$A:$H,8,FALSE),"")) -> 혼합 | E525: =IF($A525="","",IFERROR(VLOOKUP($A525,AI_PF!$A:$N,14,FALSE),"")) -> 수익증권 | F525: =IF($A525="","",IFERROR(VLOOKUP($A525,AI_PF!$A:$R,18,FALSE),"")) -> KRW | G525: =IF($A525="","",IFERROR(VLOOKUP($A525,AI_PF!$A:$T,20,FALSE),"")) -> 45985 | H525: =IF($A525="","",IFERROR(VLOOKUP($A525,AI_PF!$A:$V,22,FALSE),"")) -> 49453 | I525: =IF($A525="","",IFERROR(VLOOKUP($A525,AI_PF!$A:$EU,151,FALSE),"")) -> 2025 | J525: =IF($A525="","",IFERROR(VLOOKUP($A525,AI_PF!$A:$C,3,FALSE),"")) -> 210002230 | K525: =IF($A525="","",IFERROR(VLOOKUP($A525,Data_Raw!$A:$G,2,FALSE),"")) -> Real_Estate | L525: =IF($A525="","",IFERROR(VLOOKUP($A525,Data_Raw!$A:$G,3,FALSE),"")) -> 이지스글로벌일반사모부동산투자신탁576호(재간접형) | M525: =IF($A525="","",IFERROR(VLOOKUP($A525,Data_Raw!$A:$G,4,FALSE),"")) -> 이지스자산운용 | N525: =IF($A525="","",IFERROR(VLOOKUP($A525,AI_PF!$A:$EU,29,FALSE),"")) -> Rockwood Capital | O525: =IF($A525="","",IFERROR(VLOOKUP($A525,Data_Raw!$A:$G,5,FALSE),"")) -> US | P525: =IF($A525="","",IFERROR(VLOOKUP($A525,Data_Raw!$A:$G,6,FALSE),"")) -> 담보대출 | Q525: =IF($A525="","",IFERROR(VLOOKUP($A525,Data_Raw!$A:$G,7,FALSE),"")) -> Mixed | R525: =IF($A525="","",SUMIFS(AI_PF!$AP:$AP,AI_PF!$A:$A,$A525)) -> 150000000000 | S525: =IF($A525="","",SUMIFS(AI_PF!$AW:$AW,AI_PF!$A:$A,$A525)) -> 116308997342 | T525: =IF($A525="","",SUMIFS(AI_PF!$AZ:$AZ,AI_PF!$A:$A,$A525)) -> 0 | U525: =IF($A525="","",SUMIFS(AI_PF!$CA:$CA,AI_PF!$A:$A,$A525)) -> 116308997342 | V525: =IF($A525="","",SUMIFS(AI_PF!$CE:$CE,AI_PF!$A:$A,$A525)) -> 116658883064 | W525: =IF($A525="","",IFERROR(VLOOKUP($A525,AI_PF!$A:$CO,93,FALSE),"")) -> 1.3677809 | X525: =IF($A525="","",COUNTIF(AI_PF!$A:$A,$A525)) -> 1 | Y525: =IF($A525="","",COUNTIF(LookThrough!$A:$A,J525)) -> 0
B526: =IF($A526="","",IFERROR(VLOOKUP($A526,AI_PF!$A:$D,4,FALSE),"")) | C526: =IF($A526="","",IFERROR(VLOOKUP($A526,AI_PF!$A:$G,7,FALSE),"")) | D526: =IF($A526="","",IFERROR(VLOOKUP($A526,AI_PF!$A:$H,8,FALSE),"")) | E526: =IF($A526="","",IFERROR(VLOOKUP($A526,AI_PF!$A:$N,14,FALSE),"")) | F526: =IF($A526="","",IFERROR(VLOOKUP($A526,AI_PF!$A:$R,18,FALSE),"")) | G526: =IF($A526="","",IFERROR(VLOOKUP($A526,AI_PF!$A:$T,20,FALSE),"")) | H526: =IF($A526="","",IFERROR(VLOOKUP($A526,AI_PF!$A:$V,22,FALSE),"")) | I526: =IF($A526="","",IFERROR(VLOOKUP($A526,AI_PF!$A:$EU,151,FALSE),"")) | J526: =IF($A526="","",IFERROR(VLOOKUP($A526,AI_PF!$A:$C,3,FALSE),"")) | K526: =IF($A526="","",IFERROR(VLOOKUP($A526,Data_Raw!$A:$G,2,FALSE),"")) | L526: =IF($A526="","",IFERROR(VLOOKUP($A526,Data_Raw!$A:$G,3,FALSE),"")) | M526: =IF($A526="","",IFERROR(VLOOKUP($A526,Data_Raw!$A:$G,4,FALSE),"")) | N526: =IF($A526="","",IFERROR(VLOOKUP($A526,AI_PF!$A:$EU,29,FALSE),"")) | O526: =IF($A526="","",IFERROR(VLOOKUP($A526,Data_Raw!$A:$G,5,FALSE),"")) | P526: =IF($A526="","",IFERROR(VLOOKUP($A526,Data_Raw!$A:$G,6,FALSE),"")) | Q526: =IF($A526="","",IFERROR(VLOOKUP($A526,Data_Raw!$A:$G,7,FALSE),"")) | R526: =IF($A526="","",SUMIFS(AI_PF!$AP:$AP,AI_PF!$A:$A,$A526)) | S526: =IF($A526="","",SUMIFS(AI_PF!$AW:$AW,AI_PF!$A:$A,$A526)) | T526: =IF($A526="","",SUMIFS(AI_PF!$AZ:$AZ,AI_PF!$A:$A,$A526)) | U526: =IF($A526="","",SUMIFS(AI_PF!$CA:$CA,AI_PF!$A:$A,$A526)) | V526: =IF($A526="","",SUMIFS(AI_PF!$CE:$CE,AI_PF!$A:$A,$A526)) | W526: =IF($A526="","",IFERROR(VLOOKUP($A526,AI_PF!$A:$CO,93,FALSE),"")) | X526: =IF($A526="","",COUNTIF(AI_PF!$A:$A,$A526)) | Y526: =IF($A526="","",COUNTIF(LookThrough!$A:$A,J526))
B527: =IF($A527="","",IFERROR(VLOOKUP($A527,AI_PF!$A:$D,4,FALSE),"")) | C527: =IF($A527="","",IFERROR(VLOOKUP($A527,AI_PF!$A:$G,7,FALSE),"")) | D527: =IF($A527="","",IFERROR(VLOOKUP($A527,AI_PF!$A:$H,8,FALSE),"")) | E527: =IF($A527="","",IFERROR(VLOOKUP($A527,AI_PF!$A:$N,14,FALSE),"")) | F527: =IF($A527="","",IFERROR(VLOOKUP($A527,AI_PF!$A:$R,18,FALSE),"")) | G527: =IF($A527="","",IFERROR(VLOOKUP($A527,AI_PF!$A:$T,20,FALSE),"")) | H527: =IF($A527="","",IFERROR(VLOOKUP($A527,AI_PF!$A:$V,22,FALSE),"")) | I527: =IF($A527="","",IFERROR(VLOOKUP($A527,AI_PF!$A:$EU,151,FALSE),"")) | J527: =IF($A527="","",IFERROR(VLOOKUP($A527,AI_PF!$A:$C,3,FALSE),"")) | K527: =IF($A527="","",IFERROR(VLOOKUP($A527,Data_Raw!$A:$G,2,FALSE),"")) | L527: =IF($A527="","",IFERROR(VLOOKUP($A527,Data_Raw!$A:$G,3,FALSE),"")) | M527: =IF($A527="","",IFERROR(VLOOKUP($A527,Data_Raw!$A:$G,4,FALSE),"")) | N527: =IF($A527="","",IFERROR(VLOOKUP($A527,AI_PF!$A:$EU,29,FALSE),"")) | O527: =IF($A527="","",IFERROR(VLOOKUP($A527,Data_Raw!$A:$G,5,FALSE),"")) | P527: =IF($A527="","",IFERROR(VLOOKUP($A527,Data_Raw!$A:$G,6,FALSE),"")) | Q527: =IF($A527="","",IFERROR(VLOOKUP($A527,Data_Raw!$A:$G,7,FALSE),"")) | R527: =IF($A527="","",SUMIFS(AI_PF!$AP:$AP,AI_PF!$A:$A,$A527)) | S527: =IF($A527="","",SUMIFS(AI_PF!$AW:$AW,AI_PF!$A:$A,$A527)) | T527: =IF($A527="","",SUMIFS(AI_PF!$AZ:$AZ,AI_PF!$A:$A,$A527)) | U527: =IF($A527="","",SUMIFS(AI_PF!$CA:$CA,AI_PF!$A:$A,$A527)) | V527: =IF($A527="","",SUMIFS(AI_PF!$CE:$CE,AI_PF!$A:$A,$A527)) | W527: =IF($A527="","",IFERROR(VLOOKUP($A527,AI_PF!$A:$CO,93,FALSE),"")) | X527: =IF($A527="","",COUNTIF(AI_PF!$A:$A,$A527)) | Y527: =IF($A527="","",COUNTIF(LookThrough!$A:$A,J527))
B528: =IF($A528="","",IFERROR(VLOOKUP($A528,AI_PF!$A:$D,4,FALSE),"")) | C528: =IF($A528="","",IFERROR(VLOOKUP($A528,AI_PF!$A:$G,7,FALSE),"")) | D528: =IF($A528="","",IFERROR(VLOOKUP($A528,AI_PF!$A:$H,8,FALSE),"")) | E528: =IF($A528="","",IFERROR(VLOOKUP($A528,AI_PF!$A:$N,14,FALSE),"")) | F528: =IF($A528="","",IFERROR(VLOOKUP($A528,AI_PF!$A:$R,18,FALSE),"")) | G528: =IF($A528="","",IFERROR(VLOOKUP($A528,AI_PF!$A:$T,20,FALSE),"")) | H528: =IF($A528="","",IFERROR(VLOOKUP($A528,AI_PF!$A:$V,22,FALSE),"")) | I528: =IF($A528="","",IFERROR(VLOOKUP($A528,AI_PF!$A:$EU,151,FALSE),"")) | J528: =IF($A528="","",IFERROR(VLOOKUP($A528,AI_PF!$A:$C,3,FALSE),"")) | K528: =IF($A528="","",IFERROR(VLOOKUP($A528,Data_Raw!$A:$G,2,FALSE),"")) | L528: =IF($A528="","",IFERROR(VLOOKUP($A528,Data_Raw!$A:$G,3,FALSE),"")) | M528: =IF($A528="","",IFERROR(VLOOKUP($A528,Data_Raw!$A:$G,4,FALSE),"")) | N528: =IF($A528="","",IFERROR(VLOOKUP($A528,AI_PF!$A:$EU,29,FALSE),"")) | O528: =IF($A528="","",IFERROR(VLOOKUP($A528,Data_Raw!$A:$G,5,FALSE),"")) | P528: =IF($A528="","",IFERROR(VLOOKUP($A528,Data_Raw!$A:$G,6,FALSE),"")) | Q528: =IF($A528="","",IFERROR(VLOOKUP($A528,Data_Raw!$A:$G,7,FALSE),"")) | R528: =IF($A528="","",SUMIFS(AI_PF!$AP:$AP,AI_PF!$A:$A,$A528)) | S528: =IF($A528="","",SUMIFS(AI_PF!$AW:$AW,AI_PF!$A:$A,$A528)) | T528: =IF($A528="","",SUMIFS(AI_PF!$AZ:$AZ,AI_PF!$A:$A,$A528)) | U528: =IF($A528="","",SUMIFS(AI_PF!$CA:$CA,AI_PF!$A:$A,$A528)) | V528: =IF($A528="","",SUMIFS(AI_PF!$CE:$CE,AI_PF!$A:$A,$A528)) | W528: =IF($A528="","",IFERROR(VLOOKUP($A528,AI_PF!$A:$CO,93,FALSE),"")) | X528: =IF($A528="","",COUNTIF(AI_PF!$A:$A,$A528)) | Y528: =IF($A528="","",COUNTIF(LookThrough!$A:$A,J528))
B529: =IF($A529="","",IFERROR(VLOOKUP($A529,AI_PF!$A:$D,4,FALSE),"")) | C529: =IF($A529="","",IFERROR(VLOOKUP($A529,AI_PF!$A:$G,7,FALSE),"")) | D529: =IF($A529="","",IFERROR(VLOOKUP($A529,AI_PF!$A:$H,8,FALSE),"")) | E529: =IF($A529="","",IFERROR(VLOOKUP($A529,AI_PF!$A:$N,14,FALSE),"")) | F529: =IF($A529="","",IFERROR(VLOOKUP($A529,AI_PF!$A:$R,18,FALSE),"")) | G529: =IF($A529="","",IFERROR(VLOOKUP($A529,AI_PF!$A:$T,20,FALSE),"")) | H529: =IF($A529="","",IFERROR(VLOOKUP($A529,AI_PF!$A:$V,22,FALSE),"")) | I529: =IF($A529="","",IFERROR(VLOOKUP($A529,AI_PF!$A:$EU,151,FALSE),"")) | J529: =IF($A529="","",IFERROR(VLOOKUP($A529,AI_PF!$A:$C,3,FALSE),"")) | K529: =IF($A529="","",IFERROR(VLOOKUP($A529,Data_Raw!$A:$G,2,FALSE),"")) | L529: =IF($A529="","",IFERROR(VLOOKUP($A529,Data_Raw!$A:$G,3,FALSE),"")) | M529: =IF($A529="","",IFERROR(VLOOKUP($A529,Data_Raw!$A:$G,4,FALSE),"")) | N529: =IF($A529="","",IFERROR(VLOOKUP($A529,AI_PF!$A:$EU,29,FALSE),"")) | O529: =IF($A529="","",IFERROR(VLOOKUP($A529,Data_Raw!$A:$G,5,FALSE),"")) | P529: =IF($A529="","",IFERROR(VLOOKUP($A529,Data_Raw!$A:$G,6,FALSE),"")) | Q529: =IF($A529="","",IFERROR(VLOOKUP($A529,Data_Raw!$A:$G,7,FALSE),"")) | R529: =IF($A529="","",SUMIFS(AI_PF!$AP:$AP,AI_PF!$A:$A,$A529)) | S529: =IF($A529="","",SUMIFS(AI_PF!$AW:$AW,AI_PF!$A:$A,$A529)) | T529: =IF($A529="","",SUMIFS(AI_PF!$AZ:$AZ,AI_PF!$A:$A,$A529)) | U529: =IF($A529="","",SUMIFS(AI_PF!$CA:$CA,AI_PF!$A:$A,$A529)) | V529: =IF($A529="","",SUMIFS(AI_PF!$CE:$CE,AI_PF!$A:$A,$A529)) | W529: =IF($A529="","",IFERROR(VLOOKUP($A529,AI_PF!$A:$CO,93,FALSE),"")) | X529: =IF($A529="","",COUNTIF(AI_PF!$A:$A,$A529)) | Y529: =IF($A529="","",COUNTIF(LookThrough!$A:$A,J529))
B530: =IF($A530="","",IFERROR(VLOOKUP($A530,AI_PF!$A:$D,4,FALSE),"")) | C530: =IF($A530="","",IFERROR(VLOOKUP($A530,AI_PF!$A:$G,7,FALSE),"")) | D530: =IF($A530="","",IFERROR(VLOOKUP($A530,AI_PF!$A:$H,8,FALSE),"")) | E530: =IF($A530="","",IFERROR(VLOOKUP($A530,AI_PF!$A:$N,14,FALSE),"")) | F530: =IF($A530="","",IFERROR(VLOOKUP($A530,AI_PF!$A:$R,18,FALSE),"")) | G530: =IF($A530="","",IFERROR(VLOOKUP($A530,AI_PF!$A:$T,20,FALSE),"")) | H530: =IF($A530="","",IFERROR(VLOOKUP($A530,AI_PF!$A:$V,22,FALSE),"")) | I530: =IF($A530="","",IFERROR(VLOOKUP($A530,AI_PF!$A:$EU,151,FALSE),"")) | J530: =IF($A530="","",IFERROR(VLOOKUP($A530,AI_PF!$A:$C,3,FALSE),"")) | K530: =IF($A530="","",IFERROR(VLOOKUP($A530,Data_Raw!$A:$G,2,FALSE),"")) | L530: =IF($A530="","",IFERROR(VLOOKUP($A530,Data_Raw!$A:$G,3,FALSE),"")) | M530: =IF($A530="","",IFERROR(VLOOKUP($A530,Data_Raw!$A:$G,4,FALSE),"")) | N530: =IF($A530="","",IFERROR(VLOOKUP($A530,AI_PF!$A:$EU,29,FALSE),"")) | O530: =IF($A530="","",IFERROR(VLOOKUP($A530,Data_Raw!$A:$G,5,FALSE),"")) | P530: =IF($A530="","",IFERROR(VLOOKUP($A530,Data_Raw!$A:$G,6,FALSE),"")) | Q530: =IF($A530="","",IFERROR(VLOOKUP($A530,Data_Raw!$A:$G,7,FALSE),"")) | R530: =IF($A530="","",SUMIFS(AI_PF!$AP:$AP,AI_PF!$A:$A,$A530)) | S530: =IF($A530="","",SUMIFS(AI_PF!$AW:$AW,AI_PF!$A:$A,$A530)) | T530: =IF($A530="","",SUMIFS(AI_PF!$AZ:$AZ,AI_PF!$A:$A,$A530)) | U530: =IF($A530="","",SUMIFS(AI_PF!$CA:$CA,AI_PF!$A:$A,$A530)) | V530: =IF($A530="","",SUMIFS(AI_PF!$CE:$CE,AI_PF!$A:$A,$A530)) | W530: =IF($A530="","",IFERROR(VLOOKUP($A530,AI_PF!$A:$CO,93,FALSE),"")) | X530: =IF($A530="","",COUNTIF(AI_PF!$A:$A,$A530)) | Y530: =IF($A530="","",COUNTIF(LookThrough!$A:$A,J530))
B531: =IF($A531="","",IFERROR(VLOOKUP($A531,AI_PF!$A:$D,4,FALSE),"")) | C531: =IF($A531="","",IFERROR(VLOOKUP($A531,AI_PF!$A:$G,7,FALSE),"")) | D531: =IF($A531="","",IFERROR(VLOOKUP($A531,AI_PF!$A:$H,8,FALSE),"")) | E531: =IF($A531="","",IFERROR(VLOOKUP($A531,AI_PF!$A:$N,14,FALSE),"")) | F531: =IF($A531="","",IFERROR(VLOOKUP($A531,AI_PF!$A:$R,18,FALSE),"")) | G531: =IF($A531="","",IFERROR(VLOOKUP($A531,AI_PF!$A:$T,20,FALSE),"")) | H531: =IF($A531="","",IFERROR(VLOOKUP($A531,AI_PF!$A:$V,22,FALSE),"")) | I531: =IF($A531="","",IFERROR(VLOOKUP($A531,AI_PF!$A:$EU,151,FALSE),"")) | J531: =IF($A531="","",IFERROR(VLOOKUP($A531,AI_PF!$A:$C,3,FALSE),"")) | K531: =IF($A531="","",IFERROR(VLOOKUP($A531,Data_Raw!$A:$G,2,FALSE),"")) | L531: =IF($A531="","",IFERROR(VLOOKUP($A531,Data_Raw!$A:$G,3,FALSE),"")) | M531: =IF($A531="","",IFERROR(VLOOKUP($A531,Data_Raw!$A:$G,4,FALSE),"")) | N531: =IF($A531="","",IFERROR(VLOOKUP($A531,AI_PF!$A:$EU,29,FALSE),"")) | O531: =IF($A531="","",IFERROR(VLOOKUP($A531,Data_Raw!$A:$G,5,FALSE),"")) | P531: =IF($A531="","",IFERROR(VLOOKUP($A531,Data_Raw!$A:$G,6,FALSE),"")) | Q531: =IF($A531="","",IFERROR(VLOOKUP($A531,Data_Raw!$A:$G,7,FALSE),"")) | R531: =IF($A531="","",SUMIFS(AI_PF!$AP:$AP,AI_PF!$A:$A,$A531)) | S531: =IF($A531="","",SUMIFS(AI_PF!$AW:$AW,AI_PF!$A:$A,$A531)) | T531: =IF($A531="","",SUMIFS(AI_PF!$AZ:$AZ,AI_PF!$A:$A,$A531)) | U531: =IF($A531="","",SUMIFS(AI_PF!$CA:$CA,AI_PF!$A:$A,$A531)) | V531: =IF($A531="","",SUMIFS(AI_PF!$CE:$CE,AI_PF!$A:$A,$A531)) | W531: =IF($A531="","",IFERROR(VLOOKUP($A531,AI_PF!$A:$CO,93,FALSE),"")) | X531: =IF($A531="","",COUNTIF(AI_PF!$A:$A,$A531)) | Y531: =IF($A531="","",COUNTIF(LookThrough!$A:$A,J531))
